File: example/example12-ExperimentDataAnalysis/ppms/HcT/20201219-Sample 4.9mg.Dat
[Header]
TITLE,20201219-Sample 4.9mg.Dat
BYAPP,HeatCapacity,3.9.6,1.7
INFO,4.9,MASS:Sample Mass (mg)
INFO,,MASSERR:Sample Mass Error (mg)
INFO,,MOLWGHT:Formula Weight (g/mole)
INFO,,ATOMS:Atoms per Formula Unit
INFO,PPMS Heat Capacity Option 3.9.6 Build 3,APPNAME
DATATYPE,TIME,1
DATATYPE,COMMENT,2
STARTUPAXIS, X, 8, LINEAR, AUTO
STARTUPAXIS, Y1, 10, LINEAR, AUTO
[Data]
Time Stamp (Seconds),Comment (),System Status (Code),Puck Temp (Kelvin),System Temp (Kelvin),Field (Oersted),Pressure (Torr),Sample Temp (Kelvin),Temp Rise (Kelvin),Samp HC (µJ/K),Samp HC Err (µJ/K),Addenda HC (µJ/K),Addenda HC Err (µJ/K),Total HC (µJ/K),Total HC Err (µJ/K),Fit Deviation (ChiSquare),Time Const tau1 (seconds),Time Const tau2 (seconds),Sample Coupling (Percent),Debye Temp (Kelvin),Debye Temp Err (Kelvin),Cal Correction (Factor),Therm Resist (Ohms),Htr Resist (Ohms),Puck Resist (Ohms),Wire Cond (W/K),Meas Time (seconds),Temp Squared (K^2),Samp HC/Temp (µJ/K/K),Addenda Offset HC (µJ/K)
3817569451.90038,CALFILE: C:\QDDYNA~1\HEATCA~1\TempCal\Standard\Puck2145_1.cal|Addenda #3 measured on 12/19/2020 from 2.0224 to 100.95 K
3817569451.90739,,1857,100,100,-0.25481588,9.8999999E-6,100.74532,1.9438968,1431.2194,3.862,2154.145,1.422,3585.3645,3.862,0.065391226,42.983457,1.1514281,89.607652,,,1,,,,8.4997429E-5,84.022339,10149.619,14.206312,0
3817569777.29956,,1857,100.001,100.001,0.20627953,9.8999999E-6,100.67708,1.9512232,1435.0368,3.458,2151.2872,1.42,3586.324,3.458,0.06859261,43.351367,1.1824892,89.437118,,,1,,,,8.4336007E-5,85.966914,10135.874,14.253858,0
3817570104.68646,,1857,99.9996,99.9996,0.21841362,9.8999999E-6,100.64022,1.9622176,1436.7021,2.818,2149.7872,1.419,3586.4893,2.818,0.12749795,43.552499,1.1980965,89.356206,,,1,,,,8.3968138E-5,86.702733,10128.453,14.275626,0
3817571375.3747,,1857,90.4548,90.4548,0.19414544,9.8999999E-6,91.181133,1.9148757,1280.3714,3.542,1783.9025,1.209,3064.2738,3.542,0.078706043,39.716848,1.0654364,89.696068,,,1,,,,7.8743943E-5,87.104997,8313.9989,14.042065,0
3817571680.07627,,1857,90.4554,90.4554,0.23054773,9.8999999E-6,91.034082,1.7672714,1284.7533,2.838,1778.7157,1.206,3063.469,2.838,0.092361517,40.215143,1.1301432,89.245728,,,1,,,,7.7839202E-5,79.433696,8287.204,14.112883,0
3817571986.02591,,1857,90.4564,90.4564,0.26694998,9.8999999E-6,91.010191,1.7815588,1286.7607,2.295,1777.8686,1.206,3064.6293,2.295,0.17401,40.473564,1.1515284,89.123458,,,1,,,,7.7397169E-5,80.430286,8282.8549,14.138644,0
3817573136.25043,,1857,81.8228,81.8228,0.19414544,9.8999999E-6,82.46148,1.7428327,1138.039,3.13,1478.26,1.022,2616.299,3.13,0.081024464,36.573513,1.0112656,89.467845,,,1,,,,7.3175074E-5,80.947129,6799.8956,13.800856,0
3817573416.72505,,1857,81.8228,81.8228,0.097072721,9.8999999E-6,82.323821,1.601236,1142.1535,2.439,1473.8106,1.019,2615.9641,2.439,0.10278524,37.046905,1.0693214,89.040465,,,1,,,,7.2319486E-5,73.147026,6777.2115,13.873913,0
3817573700.77624,,1857,81.8229,81.8229,0.16987726,9.8999999E-6,82.300391,1.6149778,1144.0035,1.958,1473.0391,1.019,2617.0427,1.958,0.21848479,37.281487,1.0876712,88.931774,,,1,,,,7.1917723E-5,74.09381,6773.3543,13.900341,0
3817574745.21034,,1857,74.0128,74.0128,0.08493863,9.8999999E-6,74.578139,1.5895053,999.26226,2.706,1222.9308,0.8684,2222.1931,2.706,0.09043045,33.484471,0.94190021,89.334297,,,1,,,,6.8014602E-5,74.562974,5561.8988,13.398863,0
3817575005.37605,,1857,74.0139,74.0139,0.10920681,9.8999999E-6,74.451449,1.4568142,1002.719,2.117,1219.2371,0.8661,2221.9562,2.117,0.12229376,33.914539,0.99199696,88.938653,,,1,,,,6.722709E-5,66.968941,5543.0182,13.468093,0
3817575267.92924,,1857,74.0138,74.0138,0.10920681,9.8999999E-6,74.42762,1.4690141,1004.4629,1.71,1218.5133,0.8656,2222.9761,1.71,0.27286648,34.131507,1.0065405,88.854433,,,1,,,,6.684982E-5,67.829079,5539.4706,13.495835,0
3817576249.76117,,1857,66.9496,66.9496,0.16987726,9.8999999E-6,67.441537,1.4471069,871.07172,2.189,1015.3932,0.7376,1886.4649,2.189,0.11339976,30.57535,0.87291674,89.201182,,,1,,,,6.3339519E-5,68.263015,4548.3609,12.915953,0
3817576488.56246,,1857,66.9501,66.9501,0.13347499,9.8999999E-6,67.329357,1.3253412,873.69586,1.769,1012.3967,0.7359,1886.0926,1.769,0.16867185,30.932247,0.91346579,88.8531,,,1,,,,6.2667791E-5,61.1507,4533.2424,12.976447,0
3817576729.21352,,1857,66.9491,66.9491,0.097072721,9.8999999E-6,67.310274,1.3352915,874.8233,1.461,1011.9331,0.7357,1886.7564,1.461,0.37609771,31.117414,0.92869171,88.742063,,,1,,,,6.2339483E-5,61.864494,4530.673,12.996876,0
3817577617.8845,,1857,60.56,60.56,0.14560908,9.8999999E-6,60.993436,1.3209955,747.29856,1.879,843.83492,0.6572,1591.1335,1.879,0.1328708,27.720072,0.79394062,89.172434,,,1,,,,5.8984071E-5,62.234829,3720.1992,12.252115,0
3817577836.81041,,1857,60.56,60.56,0.15774317,9.8999999E-6,60.890934,1.2062816,749.54799,1.555,841.45932,0.6561,1591.0073,1.555,0.2132208,28.042349,0.83318225,88.791292,,,1,,,,5.8375642E-5,55.440144,3707.7058,12.309681,0
3817578057.29106,,1857,60.5594,60.5594,0.12134091,9.8999999E-6,60.869124,1.2160684,750.66862,1.313,840.9047,0.6558,1591.5733,1.313,0.4194035,28.217315,0.84423092,88.717543,,,1,,,,5.8050522E-5,56.084698,3705.0503,12.332502,0
3817578836.21728,,1857,54.7792,54.7792,0.10920681,9.8999999E-6,55.160648,1.1991767,635.7747,1.745,705.79856,0.5798,1341.5733,1.745,0.12982421,24.995066,0.72109285,89.097998,,,1,,,,5.5193563E-5,56.434631,3042.6971,11.525874,0
3817579035.95746,,1857,54.78,54.78,0.08493863,9.8999999E-6,55.062017,1.0947339,637.73322,1.362,703.71075,0.5784,1341.444,1.362,0.24533928,25.311888,0.75765131,88.71149,,,1,,,,5.4569255E-5,49.990133,3031.8257,11.58209,0
3817579237.84048,,1857,54.7789,54.7789,0.10920681,9.8999999E-6,55.045033,1.105881,637.76316,1.191,703.3854,0.5782,1341.1486,1.191,0.51081114,25.496365,0.7740423,88.559907,,,1,,,,5.418775E-5,50.623775,3029.9557,11.586207,0
3817579949.21912,,1857,49.5511,49.5511,0.10920681,9.8999999E-6,49.876136,1.0917239,535.0918,1.456,590.67667,0.5066,1125.7685,1.456,0.14840856,22.531953,0.65570348,89.007758,,,1,,,,5.1400235E-5,50.99273,2487.6289,10.728413,0
3817580130.99064,,1857,49.551,49.551,0.10920681,9.8999999E-6,49.787721,0.9981589,536.7192,1.161,588.99519,0.5056,1125.7144,1.161,0.30339222,22.801258,0.68749741,88.632805,,,1,,,,5.0856201E-5,45.063906,2478.8172,10.780152,0
3817580315.69975,,1857,49.5514,49.5514,0.10920681,9.8999999E-6,49.772286,1.0067012,537.32588,0.9928,588.65916,0.5055,1125.985,0.9928,0.83571808,22.943507,0.69583395,88.569815,,,1,,,,5.0565219E-5,45.602516,2477.2805,10.795684,0
3817580950.91147,,1857,44.8221,44.8221,0.37615678,9.8999999E-6,45.09741,0.99363821,444.69591,1.207,496.22267,0.4481,940.91858,1.207,0.18283203,20.199219,0.59391125,88.901013,,,1,,,,4.7921469E-5,45.887015,2033.7764,9.860786,0
3817581117.33647,,1857,44.8221,44.8221,0.13347499,9.8999999E-6,45.016519,0.90779619,446.07516,0.9799,494.80114,0.4469,940.8763,0.9799,0.38741835,20.459063,0.62445013,88.502734,,,1,,,,4.7374709E-5,40.398437,2026.487,9.9091438,0
3817581284.13125,,1857,44.8222,44.8222,0.12134091,9.8999999E-6,45.00224,0.91453802,446.72839,0.8802,494.56047,0.4466,941.28886,0.8802,0.94727229,20.574601,0.63133987,88.444526,,,1,,,,4.7140324E-5,40.918126,2025.2016,9.9268034,0
3817581844.95749,,1857,40.5444,40.5444,0.097072721,9.8999999E-6,40.77802,0.90458873,366.73116,1.028,417.47131,0.3743,784.20247,1.028,0.17985943,18.075,0.53528218,88.825489,,,1,,,,4.4617183E-5,41.149202,1662.8469,8.993354,0
3817581996.08636,,1857,40.5446,40.5446,0.13347499,9.8999999E-6,40.701678,0.823303,367.96948,0.8225,416.19471,0.3735,784.16419,0.8225,0.45299122,18.310726,0.56071924,88.468104,,,1,,,,4.4094626E-5,36.149999,1656.6266,9.0406466,0
3817582149.39333,,1857,40.5443,40.5443,0.12134091,9.8999999E-6,40.688542,0.82964587,368.41666,0.7285,415.99191,0.3734,784.40857,0.7285,1.1100083,18.42288,0.57084914,88.339449,,,1,,,,4.3858608E-5,36.621453,1655.5575,9.0545555,0
3817582647.16208,,1857,36.6754,36.6754,0.03640227,9.8999999E-6,36.870933,0.82346593,299.93504,0.8762,351.37953,0.3436,651.31457,0.8762,0.18790836,16.134829,0.47986433,88.776574,,,1,,,,4.1483363E-5,36.84576,1359.4657,8.1347289,0
3817582783.90053,,1857,36.6746,36.6746,0.07280454,9.8999999E-6,36.799297,0.7457583,300.66186,0.6884,350.27505,0.3427,650.93691,0.6884,0.55516974,16.356369,0.50777335,88.316408,,,1,,,,4.0957445E-5,32.269658,1354.1883,8.1703152,0
3817582921.97764,,1857,36.6747,36.6747,0.14560908,9.8999999E-6,36.788037,0.75199241,301.21639,0.6149,350.11459,0.3425,651.33098,0.6149,1.5997201,16.459278,0.51477542,88.23514,,,1,,,,4.0738281E-5,32.712739,1353.3597,8.1878897,0
3817583379.8873,,1857,33.1748,33.1748,0.097072721,9.8999999E-6,33.332345,0.74462659,243.44504,0.6895,295.02,0.276,538.46503,0.6895,0.22684283,14.415534,0.43385963,88.639997,,,1,,,,3.8362823E-5,32.918556,1111.0452,7.3035676,0
3817583490.41395,,1857,33.1746,33.1746,0.097072721,9.8999999E-6,33.272157,0.67475216,244.34579,0.6114,294.15782,0.2751,538.5036,0.6114,0.36037773,14.572037,0.45543573,88.233944,,,1,,,,3.8002883E-5,28.831069,1107.0364,7.3438518,0
3817583614.83316,,1857,33.1741,33.1741,0.10920681,9.8999999E-6,33.261894,0.68034093,244.45598,0.5043,294.01944,0.275,538.47542,0.5043,1.6649815,14.668294,0.46315278,88.121267,,,1,,,,3.7764271E-5,29.144074,1106.3536,7.3494307,0
3817584020.58423,,1857,30.0082,30.0082,0.13347499,9.8999999E-6,30.135805,0.66678948,197.11173,0.5615,246.77996,0.2403,443.89169,0.5615,0.23770288,12.87403,0.39197284,88.500158,,,1,,,,3.5391571E-5,29.336587,908.16674,6.540782,0
3817584120.89226,,1857,30.0082,30.0082,0.14560908,9.8999999E-6,30.086663,0.61212216,197.68692,0.4854,246.11181,0.2398,443.79873,0.4854,0.45316681,13.015172,0.4123016,88.069569,,,1,,,,3.5045952E-5,25.74806,905.20731,6.5705831,0
3817584222.1724,,1857,30.0076,30.0076,0.14560908,9.8999999E-6,30.078201,0.61620106,197.8066,0.4454,246.00074,0.2397,443.80734,0.4454,0.89886325,13.070268,0.41610998,88.014711,,,1,,,,3.49051E-5,26.030343,904.69819,6.5764105,0
3817584586.14865,,1857,27.1443,27.1443,0.14560908,9.8999999E-6,27.248007,0.59982164,159.31884,0.4694,205.78787,0.1957,365.10671,0.4694,0.23306392,11.490107,0.35235749,88.401743,,,1,,,,3.2595347E-5,26.140537,742.45388,5.8469906,0
3817584678.18077,,1857,27.144,27.144,0.10920681,9.8999999E-6,27.203726,0.55204501,160.15836,0.3988,205.23986,0.1949,365.39823,0.3988,0.49330471,11.662915,0.37375527,87.92225,,,1,,,,3.2184893E-5,22.980215,740.0427,5.8873687,0
3817584770.50602,,1857,27.1447,27.1447,0.16987726,9.8999999E-6,27.198109,0.55748203,160.29096,0.3629,205.17607,0.1948,365.46703,0.3629,0.91389677,11.707466,0.377471,87.854566,,,1,,,,3.207517E-5,23.32583,739.73712,5.8934596,0
3817585096.0065,,1857,24.5536,24.5536,0.15774317,9.8999999E-6,24.637427,0.53854979,130.09788,0.3765,170.83428,0.1539,300.93217,0.3765,0.22741181,10.33784,0.32029735,88.276768,,,1,,,,2.9855994E-5,23.414932,607.00282,5.2804978,0
3817585181.85897,,1857,24.5534,24.5534,0.15774317,9.8999999E-6,24.599378,0.49805933,130.49627,0.3006,170.36797,0.1535,300.86424,0.3006,0.75824062,10.452159,0.33512494,87.902246,,,1,,,,2.955555E-5,20.67568,605.12939,5.3048607,0
3817585268.55707,,1857,24.5536,24.5536,0.15774317,9.8999999E-6,24.592993,0.50125748,130.59632,0.2797,170.295,0.1535,300.89132,0.2797,1.6738505,10.49989,0.3398688,87.796009,,,1,,,,2.9432826E-5,20.904317,604.81532,5.3103061,0
3817585559.40838,,1857,22.2099,22.2099,0.14560908,9.8999999E-6,22.275945,0.4804424,107.40532,0.3126,141.10442,0.1362,248.50974,0.3126,0.23270293,9.3361717,0.28895592,88.287925,,,1,,,,2.7299158E-5,20.99978,496.21773,4.8215831,0
3817585638.98082,,1857,22.21,22.21,0.14560908,9.8999999E-6,22.242719,0.44716736,107.88233,0.2616,140.73039,0.1359,248.61272,0.2616,0.6908918,9.4586972,0.30256816,87.928995,,,1,,,,2.6986557E-5,18.672343,494.73857,4.8502311,0
3817585719.00741,,1857,22.21,22.21,0.13347499,9.8999999E-6,22.237196,0.45051436,107.94617,0.2386,140.67202,0.1358,248.61819,0.2386,1.620622,9.5046564,0.30819235,87.776699,,,1,,,,2.6867853E-5,18.917394,494.49288,4.8543066,0
3817585977.16295,,1857,20.0899,20.0899,0.14560908,9.8999999E-6,20.147851,0.42960775,90.293961,0.2746,115.57792,0.1045,205.87188,0.2746,0.20130966,8.512922,0.26086247,88.416539,,,1,,,,2.4812702E-5,19.009313,405.93589,4.4815679,0
3817586050.79534,,1857,20.0902,20.0902,0.13347499,9.8999999E-6,20.11717,0.40211167,90.763916,0.2165,115.26405,0.1041,206.02797,0.2165,0.71662171,8.6466638,0.27713512,87.926845,,,1,,,,2.4484043E-5,17.025844,404.70054,4.5117636,0
3817586125.82559,,1857,20.0902,20.0902,0.097072721,9.8999999E-6,20.112611,0.4068211,90.842572,0.1889,115.18713,0.104,206.0297,0.1889,1.9685948,8.681974,0.2777428,87.949018,,,1,,,,2.4384383E-5,17.293328,404.51714,4.516697,0
3817586359.77879,,1857,18.173,18.173,0.14560908,9.8999999E-6,18.215282,0.38327101,78.287738,0.2114,94.178486,0.08659,172.46622,0.2114,0.23126273,7.926054,0.24120435,88.524301,,,1,,,,2.2359391E-5,17.363948,331.79648,4.2979153,0
3817586429.78495,,1857,18.1732,18.1732,0.13347499,9.8999999E-6,18.192753,0.36344013,78.725666,0.1668,93.982472,0.08649,172.70814,0.1668,1.0186995,8.0401992,0.25341929,88.143405,,,1,,,,2.2101078E-5,15.852108,330.97626,4.3273092,0
3817586500.68279,,1857,18.1728,18.1728,0.18201135,9.8999999E-6,18.189171,0.3667544,78.781567,0.1586,93.951429,0.08647,172.733,0.1586,2.4855282,8.0737622,0.25622418,88.067581,,,1,,,,2.2017712E-5,16.080398,330.84594,4.3312346,0
3817586709.32308,,1857,16.4384,16.4384,0.15774317,9.8999999E-6,16.474489,0.34128136,70.16882,0.1942,76.522972,0.07554,146.69179,0.1942,0.1915618,7.4938431,0.22474965,88.688815,,,1,,,,2.0164424E-5,16.147524,271.40879,4.259241,0
3817586777.77228,,1857,16.4382,16.4382,0.15774317,9.8999999E-6,16.45547,0.3274216,70.539313,0.1476,76.354551,0.07536,146.89386,0.1476,1.0232532,7.6037853,0.23323578,88.444489,,,1,,,,1.991956E-5,14.987686,270.78251,4.2866786,0
3817586846.46318,,1857,16.4384,16.4384,0.10920681,9.8999999E-6,16.452335,0.33089507,70.492561,0.1376,76.303104,0.07531,146.79566,0.1376,2.0831762,7.6256413,0.23307086,88.483415,,,1,,,,1.9846845E-5,15.207571,270.67931,4.284654,0
3817587041.6786,,1857,14.8694,14.8694,0.10920681,9.8999999E-6,14.899277,0.30354704,64.881902,0.1624,61.715024,0.05619,126.59693,0.1624,0.21021999,7.2369766,0.20699553,89.112393,,,1,,,,1.8071547E-5,15.251283,221.98845,4.3547014,0
3817587108.63209,,1857,14.8694,14.8694,0.14560908,9.8999999E-6,14.884482,0.29568887,65.219192,0.1237,61.602318,0.05605,126.82151,0.1237,1.1454655,7.3600555,0.2156208,88.854015,,,1,,,,1.7820548E-5,14.473953,221.54782,4.3816903,0
3817587176.27772,,1857,14.8695,14.8695,0.10920681,9.8999999E-6,14.881988,0.29896743,65.241144,0.1156,61.58474,0.05603,126.82588,0.1156,3.4184176,7.3837942,0.21699322,88.820142,,,1,,,,1.7766296E-5,14.720111,221.47356,4.3838998,0
3817587353.49691,,1857,13.4505,13.4505,0.16987726,9.8999999E-6,13.4771,0.2695182,62.043297,0.1557,49.557781,0.04527,111.60108,0.1557,0.15936685,7.1647587,0.19401382,89.438978,,,1,,,,1.6161282E-5,14.767588,181.63223,4.6036088,0
3817587419.69069,,1857,13.4505,13.4505,0.15774317,9.8999999E-6,13.465797,0.26709506,62.272457,0.1119,49.468624,0.04521,111.74108,0.1119,0.93400633,7.2911707,0.20036888,89.27737,,,1,,,,1.5913991E-5,14.329517,181.32769,4.624491,0
3817587486.25185,,1857,13.45,13.45,0.10920681,9.8999999E-6,13.463397,0.26961419,62.352443,0.1036,49.452632,0.0452,111.80508,0.1036,2.6375077,7.3200809,0.20107205,89.279075,,,1,,,,1.5860941E-5,14.582341,181.26306,4.6312563,0
3817587662.81653,,1857,12.1668,12.1668,0.14560908,9.8999999E-6,12.188967,0.24030533,60.574339,0.1312,39.577347,0.03848,100.15169,0.1312,0.23005893,7.2947797,0.18232686,89.791178,,,1,,,,1.4315523E-5,14.640162,148.57091,4.9696041,0
3817587729.9561,,1857,12.1663,12.1663,0.18201135,9.8999999E-6,12.182257,0.24169425,60.75925,0.09824,39.532982,0.03843,100.29223,0.09824,1.3601644,7.4019677,0.18713285,89.664509,,,1,,,,1.4138152E-5,14.589559,148.40738,4.9875202,0
3817587796.87812,,1857,12.1664,12.1664,0.08493863,9.8999999E-6,12.180558,0.24375734,60.795136,0.09616,39.523007,0.03842,100.31814,0.09616,2.9039121,7.4219314,0.18761676,89.663267,,,1,,,,1.4104233E-5,14.803935,148.36599,4.9911618,0
3817587975.35553,,1857,11.0052,11.0052,0.13347499,9.8999999E-6,11.025503,0.21460143,59.90722,0.1104,31.498271,0.02896,91.405491,0.1104,0.32505271,7.577872,0.17179718,90.060383,,,1,,,,1.2647923E-5,14.843863,121.56172,5.4335134,0
3817588043.99132,,1857,11.0054,11.0054,0.12134091,9.8999999E-6,11.023017,0.21963886,60.010627,0.08586,31.475587,0.02895,91.486214,0.08586,1.5996769,7.6537696,0.17356263,90.04877,,,1,,,,1.2535299E-5,15.155744,121.50691,5.4441199,0
3817588113.70837,,1857,11.0057,11.0057,0.14560908,9.8999999E-6,11.021215,0.22070333,60.048214,0.08653,31.46481,0.02894,91.513024,0.08653,3.0217128,7.6665811,0.17361265,90.058874,,,1,,,,1.251773E-5,15.307539,121.46719,5.4484203,0
3817588363.35254,,1857,9.95657,9.95657,0.13347499,9.8999999E-6,9.895642,0.19170104,59.996263,0.2001,24.398392,0.02745,84.394655,0.2001,0.028910885,8.2534797,0.16455254,90.241052,,,1,,,,1.0796209E-5,15.333162,97.92373,6.0628975,0
3817588436.26644,,1857,9.95461,9.95461,0.10920681,9.8999999E-6,9.9005535,0.20090904,59.434585,0.0832,24.421073,0.02747,83.855658,0.0832,3.2382437,8.0574535,0.15912725,90.382523,,,1,,,,1.0975369E-5,16.506959,98.020959,6.0031578,0
3817588506.62798,,1857,9.95601,9.95601,0.14560908,9.8999999E-6,9.8975521,0.1973378,59.333359,0.08419,24.409086,0.02746,83.742445,0.08419,5.3485018,7.9913997,0.15917324,90.305021,,,1,,,,1.1055954E-5,16.114907,97.961538,5.9947509,0
3817588686.02289,,1857,9.00682,9.00682,0.12134091,9.8999999E-6,8.9494399,0.1702703,58.867538,0.0845,19.129484,0.01831,77.997021,0.0845,0.80687754,8.5871743,0.1454861,90.681288,,,1,,,,9.6243805E-6,15.982799,80.092475,6.5777901,0
3817588759.41199,,1857,8.9759,8.9759,0.12134091,9.8999999E-6,8.9548571,0.18112038,55.613702,0.3931,19.142448,0.01832,74.75615,0.3931,0.57281121,7.6604388,0.11471032,92.04429,,,1,,,,1.0232992E-5,17.174349,80.189465,6.2104511,0
3817588829.20854,,1857,9.00861,9.00861,0.13347499,9.8999999E-6,8.944737,0.16751369,59.071093,0.08024,19.103938,0.01827,78.175031,0.08024,3.4045766,8.6449991,0.14650089,90.653161,,,1,,,,9.5848928E-6,15.320878,80.008321,6.6040055,0
3817589004.75357,,1857,8.14564,8.14564,0.097072721,9.8999999E-6,8.0956956,0.15656967,57.222745,0.0659,14.933527,0.01581,72.156272,0.0659,1.7394576,8.9570631,0.13118608,90.814932,,,1,,,,8.5763284E-6,17.289998,65.540287,7.0682925,0
3817589081.27022,,1857,8.14497,8.14497,0.060670454,9.8999999E-6,8.0964206,0.16135573,57.428648,0.06933,14.940233,0.01581,72.368881,0.06933,0.52451281,9.0266354,0.13149894,90.846821,,,1,,,,8.5339485E-6,17.914126,65.552027,7.093091,0
3817589158.39819,,1857,8.14562,8.14562,0.15774317,9.8999999E-6,8.0957447,0.16188482,57.43578,0.06704,14.937479,0.01581,72.373259,0.06704,0.60774562,9.0301965,0.1318136,90.826017,,,1,,,,8.5324752E-6,18.053271,65.541083,7.0945641,0
3817589335.3093,,1857,7.36845,7.36845,0.10920681,9.8999999E-6,7.3216236,0.14118004,55.082619,0.05668,11.5499,0.01257,66.632518,0.05668,1.9385175,9.4257491,0.11725152,90.979912,,,1,,,,7.5546065E-6,18.060393,53.606172,7.5232792,0
3817589423.45372,,1857,7.36822,7.36822,0.12134091,9.8999999E-6,7.3230134,0.14649977,55.072408,0.05289,11.554396,0.01258,66.626804,0.05289,8.8491907,9.4502997,0.11817675,90.933955,,,1,,,,7.5369868E-6,18.851498,53.626525,7.5204571,0
3817589512.1233,,1857,7.36834,7.36834,0.13347499,9.8999999E-6,7.3223407,0.14655862,55.225961,0.05163,11.551842,0.01257,66.777803,0.05163,2.147879,9.478169,0.1177597,90.975447,,,1,,,,7.5298694E-6,18.900599,53.616673,7.5421185,0
3817589691.95023,,1857,6.66505,6.66505,0.12134091,9.8999999E-6,6.6225934,0.12928937,51.777179,0.04689,8.8754192,0.008798,60.652598,0.04689,0.48580015,9.7755412,0.10406649,91.076818,,,1,,,,6.6526354E-6,18.956338,43.858743,7.8182634,0
3817589773.88435,,1857,6.66538,6.66538,0.097072721,9.8999999E-6,6.6238763,0.133095,51.686807,0.04487,8.8781808,0.008801,60.564988,0.04487,0.52444316,9.7235367,0.10324977,91.115102,,,1,,,,6.6761518E-6,19.551082,43.875738,7.8031057,0
3817589855.45355,,1857,6.6656,6.6656,0.19414544,9.8999999E-6,6.6230442,0.13260346,51.715061,0.04133,8.8752627,0.008798,60.590324,0.04133,5.1640138,9.7574798,0.10386722,91.085742,,,1,,,,6.6574581E-6,19.447073,43.864715,7.8083521,0
3817590039.19926,,1857,6.02846,6.02846,0.21841362,9.8999999E-6,5.9914365,0.1182725,47.426377,0.0378,6.7900357,0.007288,54.216413,0.0378,1.1550246,9.8861106,0.090998324,91.149161,,,1,,,,5.8956606E-6,19.51496,35.897312,7.9156939,0
3817590130.93702,,1857,6.02833,6.02833,0.08493863,9.8999999E-6,5.9917048,0.12037919,47.561438,0.03522,6.7918539,0.007289,54.353292,0.03522,4.256563,9.9324151,0.091169435,91.156441,,,1,,,,5.8828729E-6,19.772221,35.900527,7.9378806,0
3817590213.21827,,1857,6.02853,6.02853,0.10920681,9.8999999E-6,5.9916471,0.12070159,47.525442,0.03505,6.7917257,0.007289,54.317168,0.03505,8.3869283,9.9194355,0.090961046,91.171059,,,1,,,,5.8858306E-6,19.86483,35.899835,7.9319495,0
3817590397.6343,,1857,5.45329,5.45329,0.19414544,9.8999999E-6,5.4208392,0.10864649,42.496695,0.03864,5.1316338,0.005616,47.628329,0.03864,6.6154632,9.8683943,0.07947687,91.125104,,,1,,,,5.2038456E-6,19.838871,29.385498,7.8395048,0
3817590489.21351,,1857,5.45323,5.45323,0.10920681,9.8999999E-6,5.4203883,0.1097751,42.456099,0.03308,5.1308072,0.005615,47.586907,0.03308,3.7510985,9.8859885,0.078968055,91.208522,,,1,,,,5.1860937E-6,19.736789,29.38061,7.8326675,0
3817590581.55766,,1857,5.45335,5.45335,0.10920681,9.8999999E-6,5.4201692,0.10980559,42.536327,0.03827,5.1303481,0.005615,47.666675,0.03827,1.8041583,9.915717,0.079230803,91.190407,,,1,,,,5.1802136E-6,19.771977,29.378234,7.8477859,0
3817590766.49955,,1857,4.93339,4.93339,0.10920681,9.8999999E-6,4.9041184,0.10036075,37.017115,0.0348,3.8584793,0.004224,40.875595,0.0348,9.2735772,9.6084825,0.068322815,91.152673,,,1,,,,4.5953695E-6,19.831434,24.050377,7.5481692,0
3817590847.02253,,1857,4.93269,4.93269,0.097072721,9.8999999E-6,4.9035316,0.099719519,36.848818,0.0414,3.8584287,0.004224,40.707247,0.0414,12.432554,9.5668758,0.068551029,91.115926,,,1,,,,4.5976289E-6,19.216965,24.044622,7.5147509,0
3817590928.01034,,1857,4.9333,4.9333,0.14560908,9.8999999E-6,4.9031753,0.099272323,36.964284,0.03601,3.8575473,0.004223,40.821832,0.03601,4.3234992,9.5909287,0.068115092,91.173613,,,1,,,,4.5967584E-6,19.133752,24.041128,7.5388461,0
3817591109.53017,,1857,4.46249,4.46249,0.31548634,9.8999999E-6,4.4384286,0.092633096,31.130241,0.03482,2.8907497,0.003828,34.02099,0.03482,3.8160866,9.0653895,0.059104222,91.046523,,,1,,,,4.064042E-6,19.181857,19.699648,7.0137978,0
3817591195.785,,1857,4.46208,4.46208,0.41255906,9.8999999E-6,4.4370128,0.090462458,31.109577,0.03204,2.8887817,0.003826,33.998359,0.03204,2.797142,9.0406882,0.059132742,91.015378,,,1,,,,4.0736355E-6,18.130779,19.687083,7.0113786,0
3817591272.92937,,1857,4.46244,4.46244,0.097072721,9.8999999E-6,4.4369495,0.090359401,31.09708,0.03032,2.8886415,0.003826,33.985722,0.03032,7.7686945,9.0453073,0.059066183,91.034116,,,1,,,,4.0693026E-6,18.081376,19.686521,7.0086622,0
3817591451.8539,,1857,4.0362,4.0362,0.12134091,9.8999999E-6,4.0181963,0.085502182,25.449367,0.03578,2.1530872,0.002768,27.602455,0.03578,15.78445,8.2823209,0.050304176,90.955818,,,1,,,,3.6162685E-6,18.090615,16.145902,6.3335301,0
3817591525.10446,,1857,4.03626,4.03626,0.19414544,9.8999999E-6,4.016199,0.081935295,25.452771,0.03976,2.1503154,0.002763,27.603086,0.03976,4.0066712,8.2823938,0.050717166,90.863477,,,1,,,,3.6195868E-6,16.564642,16.129854,6.3375273,0
3817591598.55515,,1857,4.03567,4.03567,0.12134091,9.8999999E-6,4.0161525,0.082106527,25.468596,0.038,2.1503542,0.002763,27.61895,0.038,10.911847,8.323645,0.050889586,90.873846,,,1,,,,3.6033854E-6,16.564788,16.129481,6.3415411,0
3817591772.39048,,1857,3.65132,3.65132,0.097072721,9.8999999E-6,3.6390908,0.079102077,20.106968,0.0339,1.6038238,0.001976,21.710792,0.0339,5.345589,7.3244394,0.043440622,90.682233,,,1,,,,3.2270911E-6,16.64729,13.242982,5.5252725,0
3817591839.54412,,1857,3.65081,3.65081,0.14560908,9.8999999E-6,3.6363611,0.0744161,20.062453,0.03212,1.6012868,0.001972,21.66374,0.03212,7.3427992,7.3465453,0.043445952,90.716979,,,1,,,,3.2093029E-6,14.648879,13.223122,5.5171784,0
3817591906.44189,,1857,3.65138,3.65138,0.15774317,9.8999999E-6,3.63644,0.074643017,20.036928,0.03527,1.6014087,0.001972,21.638336,0.03527,18.314674,7.3303653,0.043606437,90.669432,,,1,,,,3.2140464E-6,14.693091,13.223696,5.5100393,0
3817592070.93357,,1857,3.30226,3.30226,0.13347499,9.8999999E-6,3.2961143,0.072846005,15.379977,0.03165,1.1915426,0.001412,16.57152,0.03165,26.683677,6.3087189,0.037483441,90.401068,,,1,,,,2.8685802E-6,14.660731,10.86437,4.6660933,0
3817592131.3017,,1857,3.30224,3.30224,0.16987726,9.8999999E-6,3.2932655,0.067714682,15.31735,0.03216,1.1893631,0.00141,16.506713,0.03216,1.4145925,6.3084151,0.03767764,90.367171,,,1,,,,2.8583713E-6,12.617438,10.845597,4.6511129,0
3817592191.92333,,1857,3.30266,3.30266,0.12134091,9.8999999E-6,3.2933042,0.067683743,15.342496,0.03258,1.189403,0.00141,16.531899,0.03258,11.034192,6.3119751,0.037585291,90.383994,,,1,,,,2.8607013E-6,12.61683,10.845852,4.6586938,0
3817592350.81186,,1857,2.98805,2.98805,0.20627953,9.8999999E-6,2.9862019,0.067392893,11.335405,0.02666,0.89296613,0.00123,12.228371,0.02666,11.797699,5.1974694,0.032462825,90.02436,,,1,,,,2.5783226E-6,12.62395,8.9174015,3.7959273,0
3817592404.39659,,1857,2.98733,2.98733,0.18201135,9.8999999E-6,2.9825669,0.061186249,11.318229,0.02732,0.89064519,0.001228,12.208874,0.02732,22.070641,5.2693626,0.03317642,89.926159,,,1,,,,2.5415715E-6,10.394939,8.8957055,3.7947947,0
3817592459.36982,,1857,2.98757,2.98757,0.18201135,9.8999999E-6,2.9828688,0.06173661,11.32809,0.02699,0.89097699,0.001228,12.219067,0.02699,20.893619,5.2806076,0.033179111,89.943912,,,1,,,,2.5378498E-6,10.538725,8.8975065,3.7977164,0
3817592611.62167,,1857,2.7024,2.7024,0.14560908,9.8999999E-6,2.7073294,0.062549671,8.1201419,0.02323,0.6736017,0.0009125,8.7937436,0.02323,11.481716,4.2139002,0.028652233,89.581876,,,1,,,,2.2953384E-6,10.561215,7.3296323,2.999318,0
3817592660.88442,,1857,2.70186,2.70186,0.13347499,9.8999999E-6,2.7034083,0.055670857,8.1055411,0.02324,0.67156875,0.0009093,8.7771098,0.02324,56.893747,4.2457465,0.029339336,89.382898,,,1,,,,2.2782944E-6,8.4278004,7.3084164,2.9982674,0
3817592708.98884,,1857,2.70213,2.70213,0.20627953,9.8999999E-6,2.703685,0.05573371,8.122278,0.02356,0.67175239,0.0009096,8.7940304,0.02356,11.022092,4.2362632,0.029101485,89.433392,,,1,,,,2.2867171E-6,8.491493,7.3099124,3.004151,0
3817592855.18999,,1857,2.44477,2.44477,0.16987726,9.8999999E-6,2.4555283,0.05759893,5.6592144,0.01601,0.51349384,0.0007104,6.1727083,0.01601,12.772357,3.3226604,0.025386304,89.129465,,,1,,,,2.0498297E-6,8.4725265,6.0296191,2.3046831,0
3817592897.66245,,1857,2.44429,2.44429,0.20627953,9.8999999E-6,2.4516447,0.050771441,5.645257,0.01841,0.51205,0.0007089,6.157307,0.01841,7.9554199,3.3642929,0.02606883,88.956203,,,1,,,,2.0228397E-6,6.6453207,6.0105619,2.3026407,0
3817592939.76754,,1857,2.44455,2.44455,0.16987726,9.8999999E-6,2.4519996,0.051145308,5.6333924,0.01827,0.512263,0.0007092,6.1456554,0.01827,3.263466,3.3423271,0.02619197,88.845117,,,1,,,,2.0344109E-6,6.7285858,6.0123022,2.2974687,0
3817593076.89076,,1857,2.21105,2.21105,0.20627953,9.8999999E-6,2.2277982,0.052752788,3.8976353,0.01279,0.39475217,0.0006076,4.2923875,0.01279,4.2495245,2.5968164,0.023375081,88.261842,,,1,,,,1.8360275E-6,6.6846542,4.9630848,1.7495459,0
3817593115.90863,,1857,2.21102,2.21102,0.20627953,9.8999999E-6,2.224061,0.046323313,3.8670532,0.01438,0.39326037,0.0006063,4.2603135,0.01438,3.9616261,2.618222,0.024018286,88.059464,,,1,,,,1.8108389E-6,5.1936328,4.9464473,1.7387352,0
3817593154.39146,,1857,2.21108,2.21108,0.20627953,9.8999999E-6,2.2242915,0.046445545,3.8702086,0.01331,0.39334374,0.0006064,4.2635523,0.01331,33.730697,2.5983091,0.023428846,88.277966,,,1,,,,1.8222492E-6,5.2364441,4.9474725,1.7399737,0
3817593287.3728,,1857,1.99992,1.99992,0.20627953,9.8999999E-6,2.0219177,0.047333105,2.6854127,0.0088,0.30899612,0.0005195,2.9944089,0.0088,10.120675,2.0187218,0.021281479,87.588275,,,1,,,,1.6543827E-6,5.1966181,4.0881511,1.3281514,0
3817593322.31689,,1857,1.99996,1.99996,0.20627953,9.8999999E-6,2.0189353,0.04166361,2.655575,0.009239,0.30815405,0.0005184,2.9637291,0.009239,3.6993601,2.0111015,0.021477905,87.506501,,,1,,,,1.644645E-6,4.0374437,4.0760997,1.3153344,0
3817593357.46471,,1857,2.00023,2.00023,0.20627953,9.8999999E-6,2.0189166,0.041685951,2.6651912,0.00956,0.30817647,0.0005184,2.9733677,0.00956,30.067075,2.0383566,0.021752686,87.475956,,,1,,,,1.6285284E-6,4.0222029,4.0760241,1.3201096,0
3817595773.62202,Error: Warning: Current field is 40000.367 Oe;
3817595773.65872,Error: but addenda was obtained at -0.04853636 Oe.
3817596223.37785,,1857,99.9997,99.9997,40000.172,9.8999999E-6,100.48904,1.961014,1439.5786,2.56,2144.2181,1.416,3583.7967,2.56,0.22570728,44.203474,1.7013136,85.514786,,,1,,,,8.3382253E-5,87.058851,10098.047,14.325727,0
3817596558.10104,,1857,100.002,100.002,40000.039,9.8999999E-6,100.50001,1.9650004,1439.8935,2.116,2144.4854,1.416,3584.379,2.116,0.95354136,44.331541,1.7136189,85.458149,,,1,,,,8.3166095E-5,88.406948,10100.252,14.327298,0
3817596893.42633,,1857,100.001,100.001,39999.93,9.8999999E-6,100.50907,1.9678578,1440.5272,2.044,2144.8725,1.417,3585.3996,2.044,1.1862411,44.358008,1.714398,85.460469,,,1,,,,8.3140413E-5,88.663082,10102.072,14.332311,0
3817598111.76816,,1857,90.4561,90.4561,39999.664,9.8999999E-6,91.148286,1.9235257,1279.1856,3.409,1782.8611,1.209,3062.0467,3.409,0.094770875,40.041032,1.4166689,86.680195,,,1,,,,7.8600936E-5,88.716016,8308.0101,14.034116,0
3817598416.22532,,1857,90.456,90.456,39999.871,9.8999999E-6,91.00766,1.7608611,1285.7182,2.584,1777.9734,1.206,3063.6916,2.584,0.13956974,40.617695,1.4875926,86.260887,,,1,,,,7.7626189E-5,80.082064,8282.3941,14.127583,0
3817598725.51708,,1857,90.4556,90.4556,39999.871,9.8999999E-6,90.995934,1.7775763,1287.4663,2.129,1777.5687,1.206,3065.035,2.129,0.33275288,40.832292,1.5044559,86.186993,,,1,,,,7.727033E-5,81.23539,8280.2601,14.148614,0
3817599871.02476,,1857,81.8225,81.8225,39999.883,9.8999999E-6,82.467694,1.7440571,1137.8648,3.058,1478.5953,1.022,2616.4601,3.058,0.10228555,36.790205,1.265313,87.093262,,,1,,,,7.3184796E-5,81.664584,6800.9205,13.797704,0
3817600152.49946,,1857,81.8228,81.8228,39999.895,9.8999999E-6,82.333045,1.5950654,1142.6216,2.462,1474.3274,1.02,2616.949,2.462,0.14576455,37.298932,1.3309426,86.65186,,,1,,,,7.2300577E-5,73.58041,6778.7302,13.878044,0
3817600437.88318,,1857,81.8229,81.8229,39999.711,9.8999999E-6,82.311771,1.609265,1144.5664,2.062,1473.6222,1.019,2618.1886,2.062,0.25569799,37.507047,1.3462293,86.581107,,,1,,,,7.1952255E-5,74.597864,6775.2277,13.905258,0
3817601482.5309,,1857,74.0133,74.0133,40000.355,9.8999999E-6,74.594707,1.5881004,999.02357,2.784,1223.4892,0.8688,2222.5127,2.784,0.10778295,33.600461,1.1257995,87.438001,,,1,,,,6.8134026E-5,75.014094,5564.3704,13.392687,0
3817601743.45069,,1857,74.013,74.013,40000.414,9.8999999E-6,74.463011,1.4497037,1003.8945,2.175,1219.7249,0.8664,2223.6194,2.175,0.1654772,34.100054,1.1894819,86.962033,,,1,,,,6.7275763E-5,67.200922,5544.74,13.481788,0
3817602006.38966,,1857,74.0131,74.0131,40000.051,9.8999999E-6,74.446689,1.4644933,1004.4124,1.843,1219.2366,0.8661,2223.649,1.843,0.34675846,34.3104,1.203389,86.895908,,,1,,,,6.6878716E-5,68.200107,5542.3095,13.4917,0
3817602989.2273,,1857,66.9493,66.9493,39999.992,9.8999999E-6,67.457587,1.4462178,870.75604,2.219,1015.8599,0.7378,1886.6159,2.219,0.14254193,30.676441,1.0115846,87.636822,,,1,,,,6.3413733E-5,68.6208,4550.5261,12.9082,0
3817603227.44973,,1857,66.9493,66.9493,40000.004,9.8999999E-6,67.343209,1.320609,874.3457,1.838,1012.8729,0.7362,1887.2186,1.838,0.27290341,31.077321,1.0601402,87.239847,,,1,,,,6.2702681E-5,61.352883,4535.1078,12.983428,0
3817603468.49433,,1857,66.9496,66.9496,40000.016,9.8999999E-6,67.326893,1.3315244,875.99933,1.626,1012.4855,0.736,1888.4848,1.626,0.41849316,31.246654,1.0698671,87.195851,,,1,,,,6.2417599E-5,62.154642,4532.9105,13.011135,0
3817604358.79005,,1857,60.56,60.56,40000.184,9.8999999E-6,61.0068,1.3202982,747.54454,1.94,844.23749,0.6574,1591.782,1.94,0.15153495,27.809016,0.90152375,87.834018,,,1,,,,5.9048879E-5,62.493309,3721.8296,12.253463,0
3817604577.75349,,1857,60.5598,60.5598,40000.004,9.8999999E-6,60.899354,1.202557,750.78609,1.609,841.73658,0.6562,1592.5227,1.609,0.28571041,28.170091,0.9445054,87.443348,,,1,,,,5.8401418E-5,55.618033,3708.7313,12.32831,0
3817604798.81275,,1857,60.5597,60.5597,40000.086,9.8999999E-6,60.888281,1.2138081,751.30177,1.404,841.4468,0.656,1592.7486,1.404,0.63842042,28.311586,0.9516617,87.413338,,,1,,,,5.812508E-5,56.340182,3707.3828,12.339021,0
3817605583.27096,,1857,54.7808,54.7808,40000.051,9.8999999E-6,55.174665,1.1981274,636.00832,1.745,706.16181,0.58,1342.1701,1.745,0.15286196,25.068004,0.80310708,87.966737,,,1,,,,5.5241997E-5,56.623173,3044.2436,11.52718,0
3817605783.3658,,1857,54.7803,54.7803,39999.992,9.8999999E-6,55.073058,1.0923779,639.01671,1.42,704.00901,0.5786,1343.0257,1.42,0.35662672,25.427707,0.84195607,87.586741,,,1,,,,5.4572096E-5,50.136008,3033.0417,11.603073,0
3817605986.4095,,1857,54.7791,54.7791,39999.992,9.8999999E-6,55.058466,1.1029328,639.52873,1.21,703.66459,0.5784,1343.1933,1.21,0.73570811,25.559087,0.8480859,87.561958,,,1,,,,5.4304844E-5,50.855414,3031.4347,11.615448,0
3817606700.05873,,1857,49.5512,49.5512,39999.59,9.8999999E-6,49.887626,1.0909496,535.45798,1.624,590.95125,0.5068,1126.4092,1.624,0.24448937,22.607506,0.72134208,88.011656,,,1,,,,5.1410409E-5,51.118174,2488.7752,10.733283,0
3817606882.34162,,1857,49.5521,49.5521,39999.844,9.8999999E-6,49.799682,0.99646417,537.73493,1.388,589.27805,0.5058,1127.013,1.388,0.56432454,22.88986,0.75130977,87.687202,,,1,,,,5.0865515E-5,45.215013,2480.0084,10.797959,0
3817607067.94447,,1857,49.5514,49.5514,40000.316,9.8999999E-6,49.78611,1.0056517,538.33655,1.145,588.97629,0.5056,1127.3128,1.145,1.0520948,23.008818,0.75407256,87.704277,,,1,,,,5.0616111E-5,45.77972,2478.6568,10.812987,0
3817607713.38303,,1857,44.8221,44.8221,40000.223,9.8999999E-6,45.106725,0.9929801,445.62033,1.283,496.429,0.4483,942.04932,1.283,0.25040522,20.294727,0.6468633,88.024932,,,1,,,,4.7879473E-5,46.017635,2034.6166,9.8792437,0
3817607878.59724,,1857,44.8228,44.8228,40000.207,9.8999999E-6,45.027824,0.90635062,448.04673,1.127,495.03715,0.4471,943.08387,1.127,0.60463904,20.533744,0.66835495,87.785411,,,1,,,,4.7421048E-5,40.589454,2027.5049,9.9504415,0
3817608045.48754,,1857,44.8225,44.8225,40000.207,9.8999999E-6,45.015743,0.91327746,448.73895,1.099,494.83563,0.4469,943.57459,1.099,0.6926115,20.624614,0.67323641,87.752169,,,1,,,,4.7244507E-5,41.067487,2026.4172,9.9684892,0
3817608606.3831,,1857,40.5448,40.5448,40000.234,9.8999999E-6,40.788686,0.90375825,367.86908,1.159,417.68403,0.3745,785.5531,1.159,0.26521259,18.164936,0.58300479,87.948002,,,1,,,,4.4589656E-5,41.249227,1663.7169,9.0188998,0
3817608757.02898,,1857,40.5436,40.5436,40000.223,9.8999999E-6,40.714187,0.82296879,369.50682,0.9295,416.43353,0.3737,785.94035,0.9295,0.69099434,18.382121,0.59713709,87.810581,,,1,,,,4.4113075E-5,36.329872,1657.645,9.0756282,0
3817608910.18683,,1857,40.5444,40.5444,40000.207,9.8999999E-6,40.702096,0.82905994,369.77184,0.881,416.25195,0.3736,786.02378,0.881,0.92922969,18.502449,0.61350272,87.573867,,,1,,,,4.3863466E-5,36.764241,1656.6606,9.0848353,0
3817609414.4389,,1857,36.6749,36.6749,40000.223,9.8999999E-6,36.88042,0.8239232,301.48967,0.8902,351.55657,0.3437,653.04624,0.8902,0.21065372,16.228438,0.51447189,88.084446,,,1,,,,4.1440229E-5,37.004897,1360.1654,8.1747896,0
3817609552.40322,,1857,36.6749,36.6749,40000.246,9.8999999E-6,36.811432,0.74557463,302.37095,0.7673,350.48798,0.3428,652.85893,0.7673,0.71420056,16.411642,0.53565928,87.755779,,,1,,,,4.1012287E-5,32.456876,1355.0815,8.2140502,0
3817609689.79076,,1857,36.6753,36.6753,40000.234,9.8999999E-6,36.800429,0.74999454,303.3414,0.7069,350.3332,0.3427,653.6746,0.7069,1.3432979,16.543588,0.54924838,87.55933,,,1,,,,4.0764105E-5,32.823283,1354.2715,8.2428767,0
3817610146.47214,,1857,33.1736,33.1736,40000.172,9.8999999E-6,33.343192,0.74470007,245.32223,0.7009,295.20834,0.2762,540.53057,0.7009,0.28429492,14.517184,0.4679657,87.889144,,,1,,,,3.8326959E-5,33.087176,1111.7685,7.3574908,0
3817610270.97592,,1857,33.1743,33.1743,40000.195,9.8999999E-6,33.283026,0.6753663,246.65475,0.6126,294.35003,0.2753,541.00477,0.6126,0.86368012,14.713465,0.48909441,87.539326,,,1,,,,3.789589E-5,29.034369,1107.7598,7.4108269,0
3817610396.64622,,1857,33.1747,33.1747,40000.172,9.8999999E-6,33.275318,0.6818551,246.65608,0.5665,294.25105,0.2752,540.90713,0.5665,2.2471443,14.783197,0.49648676,87.419477,,,1,,,,3.7723515E-5,29.42693,1107.2468,7.4125838,0
3817610803.08015,,1857,30.0083,30.0083,40000.074,9.8999999E-6,30.147593,0.66748615,199.0437,0.5835,246.96602,0.2404,446.00972,0.5835,0.31934965,12.944132,0.41288527,87.994489,,,1,,,,3.5424542E-5,29.566394,908.87737,6.6023083,0
3817610916.22028,,1857,30.0087,30.0087,40000.039,9.8999999E-6,30.096229,0.61166788,199.84264,0.4862,246.26857,0.2399,446.11122,0.4862,1.5915616,13.13621,0.43864432,87.474819,,,1,,,,3.4970976E-5,25.888263,905.78298,6.6401225,0
3817611031.51657,,1857,30.008,30.008,40000.113,9.8999999E-6,30.089378,0.61749407,200.11997,0.4505,246.18558,0.2398,446.30555,0.4505,2.1330143,13.207583,0.44283895,87.427766,,,1,,,,3.4803544E-5,26.27242,905.37069,6.650851,0
3817611397.90317,,1857,27.1436,27.1436,40000.102,9.8999999E-6,27.257912,0.60153449,161.79232,0.4857,205.94565,0.1959,367.73798,0.4857,0.27395024,11.635294,0.37774308,87.780191,,,1,,,,3.2486451E-5,26.415167,742.99376,5.9356096,0
3817611491.0155,,1857,27.1444,27.1444,40000.113,9.8999999E-6,27.215988,0.55405895,162.44014,0.4256,205.42832,0.1952,367.86846,0.4256,0.63545977,11.779993,0.39793988,87.3251,,,1,,,,3.214388E-5,23.270589,740.71002,5.9685557,0
3817611585.22509,,1857,27.1442,27.1442,40000.102,9.8999999E-6,27.21049,0.55821616,162.63705,0.3703,205.32019,0.195,367.95723,0.3703,1.4521883,11.796565,0.39703439,87.369438,,,1,,,,3.2104454E-5,23.559986,740.41077,5.9769981,0
3817611914.60847,,1857,24.5537,24.5537,40000.148,9.8999999E-6,24.64626,0.53797406,132.40053,0.364,170.92507,0.154,303.3256,0.364,0.3588255,10.450321,0.33865935,87.790663,,,1,,,,2.9821073E-5,23.593131,607.43811,5.3720335,0
3817612000.58508,,1857,24.5535,24.5535,40000.113,9.8999999E-6,24.610469,0.49844355,132.94836,0.3334,170.52654,0.1536,303.4749,0.3334,0.91174752,10.579768,0.35516454,87.389073,,,1,,,,2.9507305E-5,20.900642,605.67521,5.402106,0
3817612086.36139,,1857,24.5541,24.5541,40000.125,9.8999999E-6,24.604799,0.50189529,133.22358,0.3051,170.46442,0.1536,303.688,0.3051,1.8690323,10.637916,0.36118562,87.257629,,,1,,,,2.9379023E-5,21.159536,605.39615,5.4145365,0
3817612370.90098,,1857,22.2096,22.2096,39999.625,9.8999999E-6,22.288631,0.48053875,109.8868,0.3619,141.27107,0.1364,251.15787,0.3619,0.27746921,9.4350189,0.30440525,87.843926,,,1,,,,2.734908E-5,21.275832,496.78307,4.9301726,0
3817612450.19021,,1857,22.21,22.21,39999.625,9.8999999E-6,22.254301,0.44622448,110.46836,0.3008,140.88472,0.136,251.35308,0.3008,0.85725305,9.5834713,0.32200075,87.382795,,,1,,,,2.6985449E-5,18.870038,495.25393,4.9639105,0
3817612529.60687,,1857,22.2102,22.2102,39999.664,9.8999999E-6,22.249422,0.45067426,110.51749,0.2812,140.83609,0.136,251.35358,0.2812,1.464464,9.6307783,0.32746036,87.243446,,,1,,,,2.6863507E-5,19.166943,495.03678,4.9672072,0
3817612785.94162,,1857,20.09,20.09,40000.402,9.8999999E-6,20.157613,0.42952758,92.904176,0.292,115.70365,0.1046,208.60782,0.292,0.23899265,8.6537085,0.27909122,87.868486,,,1,,,,2.4788935E-5,19.261557,406.32937,4.6088877,0
3817612861.23328,,1857,20.09,20.09,40000.402,9.8999999E-6,20.128416,0.40318772,93.269292,0.231,115.37335,0.1042,208.64264,0.231,1.1029676,8.7708299,0.29148282,87.528429,,,1,,,,2.4489577E-5,17.307417,405.15311,4.6337125,0
3817612938.00324,,1857,20.0902,20.0902,40000.414,9.8999999E-6,20.123428,0.40667106,93.342345,0.2166,115.32291,0.1042,208.66526,0.2166,1.754044,8.8082575,0.29221978,87.549121,,,1,,,,2.4387735E-5,17.54166,404.95236,4.6384912,0
[...]
3817618153.35159,,1857,4.03633,4.03633,40000.27,9.8999999E-6,4.0293068,0.085870411,21.954172,0.03564,2.1705493,0.002796,24.124721,0.03564,3.0921086,7.1382594,0.051391585,90.593519,,,1,,,,3.6725372E-6,16.002042,16.235314,5.4486226,0
3817618218.83147,,1857,4.03606,4.03606,40000.207,9.8999999E-6,4.0266813,0.081442256,21.87912,0.03485,2.1667381,0.00279,24.045858,0.03485,10.754302,7.1405791,0.051475948,90.594511,,,1,,,,3.6592239E-6,14.276519,16.214162,5.4335365,0
3817618284.54433,,1857,4.03633,4.03633,40000.223,9.8999999E-6,4.0265963,0.0814837,21.880129,0.03306,2.1666206,0.002789,24.046749,0.03306,7.4949001,7.1448834,0.051501712,90.594685,,,1,,,,3.6571542E-6,14.281158,16.213478,5.4339018,0
3817618450.52364,,1857,3.65109,3.65109,40000.207,9.8999999E-6,3.6529572,0.079476313,16.817138,0.03074,1.621668,0.002002,18.438806,0.03074,7.160456,6.1268446,0.04390876,90.42281,,,1,,,,3.2767481E-6,14.289767,13.344096,4.6037053,0
3817618511.18077,,1857,3.65097,3.65097,40000.234,9.8999999E-6,3.6498393,0.073698612,16.70013,0.03191,1.6186591,0.001998,18.318789,0.03191,10.708268,6.0996949,0.044504172,90.281315,,,1,,,,3.2740703E-6,12.253689,13.321327,4.5755796,0
3817618570.80426,,1857,3.65101,3.65101,40000.172,9.8999999E-6,3.6495656,0.073635228,16.761165,0.03083,1.6183939,0.001997,18.379559,0.03083,3.6023875,6.157413,0.044524985,90.341175,,,1,,,,3.2524638E-6,12.19939,13.319329,4.5926467,0
3817618728.42628,,1857,3.30275,3.30275,40000.246,9.8999999E-6,3.3138101,0.073642788,12.39895,0.02933,1.2101157,0.001429,13.609066,0.02933,11.944271,5.0525812,0.037302105,90.218822,,,1,,,,2.9378497E-6,12.314826,10.981337,3.7415994,0
3817618781.70969,,1857,3.30237,3.30237,40000.172,9.8999999E-6,3.3101466,0.066620355,12.411324,0.02866,1.2072409,0.001426,13.618564,0.02866,4.6294766,5.1207776,0.038511363,89.989351,,,1,,,,2.9072286E-6,10.105162,10.95707,3.7494785,0
3817618836.31411,,1857,3.30269,3.30269,40000.223,9.8999999E-6,3.3105315,0.067277336,12.365992,0.02739,1.207659,0.001427,13.573651,0.02739,11.529615,5.0819572,0.038041372,90.076793,,,1,,,,2.9171758E-6,10.241555,10.959619,3.7353494,0
3817618986.76021,,1857,2.98762,2.98762,40000.223,9.8999999E-6,3.0078866,0.068264952,8.8136624,0.02125,0.91148173,0.001246,9.7251442,0.02125,20.687433,4.0715303,0.032686686,89.843058,,,1,,,,2.6123246E-6,10.163914,9.0473817,2.9301844,0
3817619035.11355,,1857,2.98755,2.98755,40000.223,9.8999999E-6,3.0041198,0.061047152,8.7435723,0.02225,0.90911788,0.001244,9.6526902,0.02225,5.8778824,4.0594764,0.033208409,89.684461,,,1,,,,2.6042511E-6,8.1430606,9.0247359,2.9105272,0
3817619083.31681,,1857,2.98695,2.98695,40000.195,9.8999999E-6,3.0038798,0.060895101,8.7646151,0.01977,0.90892161,0.001244,9.6735367,0.01977,18.896425,4.0745368,0.03335721,89.651003,,,1,,,,2.6011609E-6,8.1189528,9.0232941,2.9177649,0
3817619226.62618,,1857,2.70226,2.70226,40000.207,9.8999999E-6,2.7326004,0.063131227,6.0338387,0.01582,0.69124963,0.0009408,6.7250883,0.01582,18.726624,3.1346372,0.028659718,89.340713,,,1,,,,2.3535536E-6,8.1490736,7.4671051,2.208094,0
3817619267.86159,,1857,2.702,2.702,40000.137,9.8999999E-6,2.7286283,0.055557123,5.9677798,0.01764,0.68938945,0.0009378,6.6571692,0.01764,6.4837251,3.1366328,0.029242284,89.193612,,,1,,,,2.3311737E-6,6.2692744,7.4454122,2.1870989,0
3817619309.3682,,1857,2.70212,2.70212,40000.184,9.8999999E-6,2.7285768,0.055553066,5.9771447,0.018,0.68936928,0.0009377,6.666514,0.018,13.932816,3.1433153,0.029465287,89.113359,,,1,,,,2.3313049E-6,6.2732655,7.4451314,2.1905723,0
3817619485.29945,,1857,2.44452,2.44452,40000.195,9.8999999E-6,2.4807332,0.050659972,3.9438976,0.01475,0.52913051,0.000726,4.4730281,0.01475,11.706899,2.3822282,0.026492674,88.537902,,,1,,,,2.0689837E-6,4.6974841,6.154037,1.5898113,0
3817619523.34176,,1857,2.44387,2.44387,40000.172,9.8999999E-6,2.4809909,0.051241758,3.9418785,0.01249,0.52840978,0.0007253,4.4702883,0.01249,8.4357694,2.3646631,0.026087733,88.62884,,,1,,,,2.0813691E-6,4.7644564,6.1553158,1.5888323,0
3817619561.66988,,1857,2.44431,2.44431,40000.137,9.8999999E-6,2.4806878,0.050862761,3.9462575,0.01274,0.52818931,0.000725,4.4744468,0.01274,1.6868943,2.3560466,0.025741924,88.733036,,,1,,,,2.0889876E-6,4.7293262,6.1538122,1.5907916,0
3817619723.34809,,1857,2.21091,2.21091,40000.195,9.8999999E-6,2.2577439,0.046028216,2.5303913,0.00944,0.40950043,0.00062,2.9398917,0.00944,9.2068056,1.7444892,0.023614828,87.914915,,,1,,,,1.8594652E-6,3.422033,5.0974075,1.120761,0
3817619757.05171,,1857,2.21086,2.21086,40000.207,9.8999999E-6,2.2579914,0.046641179,2.5359932,0.009381,0.40967756,0.0006201,2.9456707,0.009381,25.904974,1.7561205,0.023579553,88.003324,,,1,,,,1.8494011E-6,3.4889784,5.098525,1.1231191,0
3817619790.65166,,1857,2.21112,2.21112,40000.184,9.8999999E-6,2.257977,0.046640817,2.5425725,0.009566,0.40966907,0.0006201,2.9522416,0.009566,14.477389,1.7518664,0.023678226,87.89061,,,1,,,,1.860022E-6,3.5122409,5.0984603,1.12604,0
3817619947.04622,,1857,1.99993,1.99993,40000.172,9.8999999E-6,2.056127,0.042168747,1.5944743,0.007146,0.32257568,0.0005367,1.9170499,0.007146,5.657581,1.2739658,0.021592914,87.136295,,,1,,,,1.6613975E-6,2.5123212,4.2276581,0.7754746,0
3817619976.86491,,1857,1.99996,1.99996,40000.172,9.8999999E-6,2.0561597,0.042377679,1.5975847,0.006918,0.32259181,0.0005367,1.9201765,0.006918,7.7209637,1.2675363,0.021555081,87.071172,,,1,,,,1.6735781E-6,2.5479316,4.2277925,0.77697501,0
3817620007.89826,,1857,2.00004,2.00004,40000.16,9.8999999E-6,2.0560309,0.042278447,1.5990963,0.006998,0.32253275,0.0005366,1.921629,0.006998,7.9062701,1.2674413,0.021394105,87.162908,,,1,,,,1.6737119E-6,2.5350726,4.2272632,0.77775886,0
3817622883.63122,Error: Warning: Current field is 80000.164 Oe;
3817622883.6609,Error: but addenda was obtained at -0.04853636 Oe.
3817623331.11864,,1857,100.001,100.001,79999.602,9.8999999E-6,100.49692,1.9582175,1439.7008,2.729,2144.5967,1.416,3584.2975,2.729,0.22807353,44.272252,1.771352,84.99663,,,1,,,,8.3365097E-5,87.058851,10099.63,14.32582,0
3817623666.0276,,1857,100,100,79999.594,9.8999999E-6,100.4994,1.9644307,1439.5608,2.267,2144.5153,1.416,3584.0761,2.267,0.87359212,44.345433,1.7740415,84.998351,,,1,,,,8.3221875E-5,88.544503,10100.13,14.324073,0
3817624004.81587,,1857,100,100,79999.742,9.8999999E-6,100.51106,1.9656253,1439.3058,2.129,2144.9863,1.417,3584.2921,2.129,1.131391,44.331047,1.7689478,85.032236,,,1,,,,8.324611E-5,88.690866,10102.473,14.319875,0
3817625218.21014,,1857,90.4567,90.4567,79999.742,9.8999999E-6,91.142594,1.9209398,1279.0834,3.46,1782.6977,1.209,3061.7811,3.46,0.095796309,40.103513,1.4790781,86.16295,,,1,,,,7.857113E-5,88.662094,8306.9725,14.033871,0
3817625524.35801,,1857,90.456,90.456,79999.68,9.8999999E-6,91.00407,1.7600953,1286.1401,2.738,1777.9019,1.206,3064.042,2.738,0.17767092,40.686512,1.5501517,85.75561,,,1,,,,7.7602618E-5,80.207026,8281.7407,14.132776,0
3817625833.89824,,1857,90.4564,90.4564,79999.773,9.8999999E-6,90.990631,1.7768852,1287.8968,2.266,1777.4386,1.205,3065.3354,2.266,0.33710879,40.915427,1.5690215,85.672855,,,1,,,,7.7221468E-5,81.373024,8279.295,14.154169,0
3817626983.99045,,1857,81.8235,81.8235,79999.773,9.8999999E-6,82.460763,1.7437735,1137.4945,3.098,1478.4312,1.022,2615.9257,3.098,0.1165429,36.914384,1.3419173,86.415634,,,1,,,,7.3053E-5,81.830855,6799.7774,13.794373,0
3817627267.06295,,1857,81.8231,81.8231,79999.813,9.8999999E-6,82.335622,1.596602,1142.5809,2.541,1474.366,1.02,2616.9469,2.541,0.22363397,37.316435,1.3774926,86.227883,,,1,,,,7.2348231E-5,73.828768,6779.1547,13.877115,0
3817627553.00481,,1857,81.8229,81.8229,79999.789,9.8999999E-6,82.31069,1.6065741,1146.4741,2.217,1473.6232,1.019,2620.0973,2.217,0.31361403,37.571109,1.3963577,86.144158,,,1,,,,7.1970338E-5,74.632871,6775.0497,13.928617,0
3817628598.14295,,1857,74.0128,74.0128,79999.789,9.8999999E-6,74.592677,1.5884435,999.5693,2.859,1223.4697,0.8688,2223.039,2.859,0.14452612,33.676228,1.1777408,86.927869,,,1,,,,6.8094205E-5,75.142218,5564.0675,13.400368,0
3817628859.04544,,1857,74.014,74.014,79999.742,9.8999999E-6,74.46509,1.4493794,1004.8145,2.342,1219.817,0.8665,2224.6314,2.342,0.25700149,34.132307,1.2247458,86.615777,,,1,,,,6.7310459E-5,67.352455,5545.0496,13.493766,0
3817629122.70389,,1857,74.0142,74.0142,79999.742,9.8999999E-6,74.444047,1.4628854,1006.4518,1.978,1219.1916,0.8661,2225.6433,1.978,0.38113723,34.389219,1.2468702,86.486775,,,1,,,,6.6867537E-5,68.264614,5541.9162,13.519573,0
3817630110.16655,,1857,66.9491,66.9491,79999.711,9.8999999E-6,67.459778,1.4469903,872.6792,2.298,1015.9586,0.7379,1888.6378,2.298,0.1630113,30.774109,1.0536137,87.19616,,,1,,,,6.3365563E-5,68.778439,4550.8217,12.936289,0
3817630352.59103,,1857,66.9492,66.9492,79999.703,9.8999999E-6,67.344945,1.3210937,875.32264,1.977,1012.9495,0.7362,1888.2721,1.977,0.26516676,31.127077,1.0922463,86.899451,,,1,,,,6.2702484E-5,61.548218,4535.3416,12.9976,0
3817630596.5389,,1857,66.9496,66.9496,79999.641,9.8999999E-6,67.325216,1.3305391,877.82108,1.678,1012.386,0.7359,1890.2071,1.678,0.61861038,31.29728,1.0992903,86.887625,,,1,,,,6.2435026E-5,62.254154,4532.6847,13.038518,0
3817631489.43195,,1857,60.5594,60.5594,79999.727,9.8999999E-6,61.008392,1.3193532,750.17397,1.963,844.30686,0.6574,1594.4808,1.963,0.16228574,27.922251,0.93879343,87.411171,,,1,,,,5.8990235E-5,62.594559,3722.0239,12.296242,0
3817631709.94548,,1857,60.5599,60.5599,79999.742,9.8999999E-6,60.904352,1.2036033,752.92674,1.641,841.89528,0.6563,1594.822,1.641,0.31599326,28.265634,0.97759903,87.072744,,,1,,,,5.8358982E-5,55.844502,3709.3401,12.362446,0
3817631933.52338,,1857,60.5596,60.5596,79999.68,9.8999999E-6,60.887501,1.2137482,753.82772,1.424,841.4563,0.6561,1595.284,1.424,0.73313477,28.401856,0.98366697,87.055744,,,1,,,,5.8102425E-5,56.531267,3707.2877,12.380665,0
3817632744.04265,,1857,54.7794,54.7794,79999.727,9.8999999E-6,55.169384,1.1991686,640.24009,1.689,706.08258,0.5799,1346.3227,1.689,0.20811906,25.254711,0.83866333,87.553053,,,1,,,,5.5084565E-5,56.803711,3043.6609,11.604989,0
3817632945.386,,1857,54.7797,54.7797,79999.75,9.8999999E-6,55.073167,1.0944214,642.84799,1.455,704.04266,0.5786,1346.8906,1.455,0.35566763,25.535399,0.86756217,87.282002,,,1,,,,5.4560586E-5,50.509422,3033.0537,11.672617,0
3817633148.49969,,1857,54.7796,54.7796,79999.711,9.8999999E-6,55.058981,1.1026666,643.04933,1.246,703.70407,0.5784,1346.7534,1.246,0.76232462,25.677241,0.87853789,87.197667,,,1,,,,5.4269382E-5,51.070798,3031.4914,11.679281,0
3817633864.13426,,1857,49.5517,49.5517,79999.75,9.8999999E-6,49.892006,1.0909528,540.03327,1.639,591.06811,0.5068,1131.1014,1.639,0.29522293,22.73515,0.74866318,87.649223,,,1,,,,5.1405545E-5,51.354482,2489.2123,10.824044,0
3817634046.75904,,1857,49.5515,49.5515,79999.75,9.8999999E-6,49.804629,0.9978757,542.17816,1.449,589.34922,0.5058,1131.5274,1.449,0.47606359,23.019838,0.77008518,87.463043,,,1,,,,5.0830061E-5,45.470301,2480.501,10.8861,0
3817634231.77586,,1857,49.5512,49.5512,79999.688,9.8999999E-6,49.790191,1.0057155,541.88448,1.279,589.08549,0.5057,1130.97,1.279,0.78486001,23.120157,0.78170925,87.337352,,,1,,,,5.0604223E-5,46.039675,2479.0631,10.883358,0
3817634874.13427,,1857,44.8211,44.8211,79999.664,9.8999999E-6,45.11257,0.99271248,450.28026,1.358,496.55465,0.4484,946.83491,1.358,0.26742187,20.39169,0.65998483,87.84981,,,1,,,,4.7934977E-5,46.240313,2035.144,9.9812594,0
3817635040.53107,,1857,44.822,44.822,79999.688,9.8999999E-6,45.03269,0.90695945,451.53403,1.169,495.15598,0.4472,946.69002,1.169,0.4933978,20.679972,0.6956959,87.39956,,,1,,,,4.7333627E-5,40.78338,2027.9432,10.026806,0
3817635208.7255,,1857,44.8224,44.8224,79999.68,9.8999999E-6,45.020746,0.91472588,453.04929,1.001,494.90543,0.4469,947.95472,1.001,1.3206053,20.782794,0.69541569,87.461718,,,1,,,,4.7159549E-5,41.359945,2026.8675,10.063123,0
3817635769.11007,,1857,40.5443,40.5443,79999.594,9.8999999E-6,40.795441,0.90633415,372.60191,1.142,417.77951,0.3745,790.38142,1.142,0.22763026,18.304314,0.59943208,87.717476,,,1,,,,4.4570769E-5,41.565588,1664.268,9.1334203,0
3817635922.0151,,1857,40.5434,40.5434,79999.633,9.8999999E-6,40.719075,0.82259427,373.97838,0.9298,416.53914,0.3738,790.51752,0.9298,0.73652372,18.515969,0.61914369,87.474084,,,1,,,,4.4111034E-5,36.608628,1658.0431,9.1843534,0
3817636075.75396,,1857,40.5442,40.5442,79999.594,9.8999999E-6,40.707581,0.82857088,374.5802,0.8414,416.36158,0.3736,790.94177,0.8414,1.2219992,18.614065,0.62460152,87.432675,,,1,,,,4.3910676E-5,37.031939,1657.1071,9.2017308,0
3817636577.19308,,1857,36.6747,36.6747,79999.617,9.8999999E-6,36.886065,0.8230921,306.46501,0.9323,351.62409,0.3438,658.0891,0.9323,0.24764224,16.378574,0.53548275,87.737168,,,1,,,,4.1440268E-5,37.22813,1360.5818,8.3084225,0
3817636715.62689,,1857,36.6747,36.6747,79999.57,9.8999999E-6,36.815661,0.74520846,308.14207,0.7918,350.58209,0.3429,658.72416,0.7918,0.90359482,16.621415,0.55732119,87.443922,,,1,,,,4.0920956E-5,32.757148,1355.3929,8.3698639,0
3817636855.18995,,1857,36.6748,36.6748,79999.641,9.8999999E-6,36.80646,0.75310487,308.16434,0.7445,350.41284,0.3428,658.57718,0.7445,1.6332246,16.719237,0.5678052,87.293077,,,1,,,,4.0691489E-5,33.24283,1354.7155,8.3725613,0
3817637313.88249,,1857,33.1744,33.1744,79999.57,9.8999999E-6,33.347897,0.7451139,251.53042,0.7609,295.30631,0.2763,546.83674,0.7609,0.28765992,14.72235,0.486426,87.613409,,,1,,,,3.8293519E-5,33.438475,1112.0823,7.5426171,0
3817637439.37822,,1857,33.1745,33.1745,79999.742,9.8999999E-6,33.28729,0.67628932,252.45871,0.684,294.44101,0.2754,546.89972,0.684,1.0405302,14.912847,0.50879822,87.237458,,,1,,,,3.7858059E-5,29.4447,1108.0437,7.5842374,0
3817637553.48194,,1857,33.1748,33.1748,79999.688,9.8999999E-6,33.281719,0.68259204,252.39199,0.6302,294.32317,0.2753,546.71517,0.6302,0.60006604,14.930749,0.50707703,87.291989,,,1,,,,3.7794085E-5,29.825695,1107.6728,7.5835024,0
3817637951.18436,,1857,30.008,30.008,79999.656,9.8999999E-6,30.154254,0.66492722,205.19431,0.6521,247.04074,0.2405,452.23505,0.6521,0.25002899,13.134089,0.43024558,87.705785,,,1,,,,3.5460516E-5,29.861499,909.27904,6.8048212,0
3817638052.939,,1857,30.0084,30.0084,79999.617,9.8999999E-6,30.102522,0.60985801,206.43281,0.5552,246.37908,0.24,452.8119,0.5552,0.57198418,13.340519,0.45590839,87.213506,,,1,,,,3.5014666E-5,26.268178,906.16183,6.8576585,0
3817638156.34271,,1857,30.0086,30.0086,79999.688,9.8999999E-6,30.09569,0.61753837,206.14172,0.5298,246.25434,0.2399,452.39606,0.5298,0.9762188,13.383506,0.4572925,87.215484,,,1,,,,3.4868899E-5,26.681038,905.75056,6.8495429,0
3817638514.08923,,1857,27.1442,27.1442,79999.555,9.8999999E-6,27.263971,0.59903659,167.92416,0.519,206.00988,0.196,373.93404,0.519,0.2362558,11.839629,0.39845688,87.385275,,,1,,,,3.2535739E-5,26.767013,743.32414,6.1591966,0
3817638608.30321,,1857,27.1443,27.1443,79999.594,9.8999999E-6,27.220267,0.55266718,168.87982,0.442,205.46717,0.1952,374.347,0.442,0.73517338,11.998043,0.41861158,86.958808,,,1,,,,3.218853E-5,23.679258,740.94292,6.2041943,0
3817638703.68562,,1857,27.1439,27.1439,79999.602,9.8999999E-6,27.21434,0.55797847,169.06353,0.4205,205.40141,0.1951,374.46494,0.4205,1.3253498,12.07136,0.42438657,86.866854,,,1,,,,3.2012905E-5,23.996087,740.62028,6.212296,0
3817639038.19976,,1857,24.5532,24.5532,79999.82,9.8999999E-6,24.648102,0.53810998,139.07356,0.4113,170.97902,0.154,310.05258,0.4113,0.35482024,10.749162,0.37029809,87.107765,,,1,,,,2.973489E-5,24.142721,607.52892,5.6423641,0
3817639126.64207,,1857,24.5534,24.5534,79999.836,9.8999999E-6,24.612375,0.49950498,139.68553,0.3534,170.54216,0.1537,310.2277,0.3534,0.89536528,10.858685,0.38090219,86.892225,,,1,,,,2.9476117E-5,21.498324,605.76903,5.6754185,0
3817639214.33274,,1857,24.5538,24.5538,79999.844,9.8999999E-6,24.607761,0.50312132,139.68633,0.3328,170.49109,0.1536,310.17742,0.3328,1.9602716,10.890643,0.38382122,86.835104,,,1,,,,2.9389866E-5,21.71737,605.5419,5.6765152,0
3817639512.3155,,1857,22.21,22.21,79999.898,9.8999999E-6,22.283901,0.47990442,116.46562,0.6439,141.21901,0.1363,257.68463,0.6439,0.81515011,9.8407424,0.35754935,86.460234,,,1,,,,2.7055832E-5,21.781286,496.57226,5.2264465,0
3817639594.82891,,1857,22.21,22.21,79999.836,9.8999999E-6,22.254704,0.45048542,116.73099,0.6702,140.8896,0.136,257.62059,0.6702,1.5871886,9.8990138,0.35308739,86.691441,,,1,,,,2.6876511E-5,19.681485,495.27183,5.2452279,0
3817639678.47313,,1857,22.21,22.21,79999.844,9.8999999E-6,22.249777,0.4532773,116.16494,0.6532,140.83163,0.136,256.99657,0.6532,2.5463334,9.8969819,0.34810919,86.861772,,,1,,,,2.6799862E-5,19.798028,495.05259,5.2209482,0
3817639938.83934,,1857,20.0898,20.0898,79999.836,9.8999999E-6,20.154946,0.42808041,98.920363,0.3357,115.66553,0.1046,214.58589,0.3357,0.36905992,8.9519998,0.30831444,87.124626,,,1,,,,2.4751261E-5,19.793964,406.22185,4.9079944,0
3817640015.90582,,1857,20.0901,20.0901,79999.898,9.8999999E-6,20.12628,0.40259768,99.609332,0.3577,115.37746,0.1042,214.98679,0.3577,0.9398286,9.1119144,0.32590981,86.664022,,,1,,,,2.440338E-5,17.904,405.06713,4.9492173,0
3817640093.20393,,1857,20.0903,20.0903,79999.82,9.8999999E-6,20.122338,0.40761222,99.465884,0.3161,115.34162,0.1042,214.8075,0.3161,1.1675611,9.1466056,0.32763385,86.64566,,,1,,,,2.4290896E-5,18.223829,404.90849,4.9430579,0
3817640324.33805,,1857,18.1726,18.1726,79999.82,9.8999999E-6,18.228987,0.38335034,86.072525,0.2803,94.331603,0.08668,180.40413,0.2803,0.45670746,8.3666444,0.29358495,86.89172,,,1,,,,2.2330682E-5,18.293211,332.29596,4.7217394,0
3817640398.14328,,1857,18.1729,18.1729,79999.82,9.8999999E-6,18.205678,0.36366022,86.908366,0.2343,94.127464,0.08657,181.03583,0.2343,1.757434,8.5209755,0.30427451,86.671073,,,1,,,,2.2027846E-5,16.733289,331.44673,4.7736956,0
3817640472.20117,,1857,18.1727,18.1727,79999.82,9.8999999E-6,18.203227,0.36782119,86.990184,0.2371,94.108282,0.08656,181.09847,0.2371,1.9889897,8.5434121,0.30447555,86.695122,,,1,,,,2.1976842E-5,17.041951,331.35748,4.778833,0
3817640685.29393,,1857,16.4382,16.4382,79999.844,9.8999999E-6,16.483077,0.34184038,77.088621,0.2411,76.614626,0.07563,153.70325,0.2411,0.39099575,7.9492792,0.27564024,86.975222,,,1,,,,2.0091076E-5,17.086824,271.69183,4.6768344,0
3817640756.95813,,1857,16.4383,16.4383,79999.766,9.8999999E-6,16.464951,0.32863108,77.460289,0.218,76.456025,0.07547,153.91631,0.218,1.2166896,8.0759641,0.28565307,86.721903,,,1,,,,1.9825872E-5,15.898558,271.09463,4.7045562,0
3817640828.87579,,1857,16.4385,16.4385,79999.797,9.8999999E-6,16.462216,0.33116133,77.548346,0.2113,76.431897,0.07544,153.98024,0.2113,2.7938611,8.0775633,0.28262434,86.855684,,,1,,,,1.9822047E-5,16.151928,271.00455,4.710687,0
3817641029.25127,,1857,14.8697,14.8697,79999.797,9.8999999E-6,14.900051,0.30366389,70.404896,0.2081,61.750393,0.05623,132.15529,0.2081,0.3892331,7.6544917,0.2657795,86.784643,,,1,,,,1.8039329E-5,16.155127,222.01151,4.7251447,0
3817641099.5777,,1857,14.8694,14.8694,79999.773,9.8999999E-6,14.886377,0.29621325,70.62184,0.175,61.625075,0.05608,132.24691,0.175,1.6641846,7.7611518,0.27177764,86.667927,,,1,,,,1.7815497E-5,15.308983,221.60423,4.7440582,0
3817641169.42231,,1857,14.8696,14.8696,79999.773,9.8999999E-6,14.883729,0.29832031,70.771128,0.1755,61.606181,0.05605,132.37731,0.1755,2.6907745,7.8082727,0.27527843,86.577342,,,1,,,,1.7733472E-5,15.522304,221.52538,4.7549327,0
3817641350.25098,,1857,13.4503,13.4503,79999.711,9.8999999E-6,13.469295,0.27038361,65.503206,0.1956,49.49929,0.04523,115.0025,0.1956,0.39123461,7.5006034,0.25813181,86.546111,,,1,,,,1.6134742E-5,15.616545,181.4219,4.8631505,0
3817641417.7719,,1857,13.4503,13.4503,79999.703,9.8999999E-6,13.457392,0.26572791,65.85687,0.1681,49.422546,0.04519,115.27942,0.1681,1.9633622,7.6333852,0.26500429,86.411744,,,1,,,,1.590646E-5,15.001207,181.10139,4.8937321,0
3817641486.66489,,1857,13.4505,13.4505,79999.711,9.8999999E-6,13.455612,0.26909943,65.987031,0.1559,49.394264,0.04517,115.38129,0.1559,2.387351,7.680656,0.26761435,86.356385,,,1,,,,1.5828188E-5,15.26677,181.0535,4.9040526,0
3817684139.58789,,1857,12.1664,12.1664,80000.32,9.8999999E-6,13.722307,3.3776968,-13.434175,0.1157,51.304251,0.04637,37.870075,0.106,6974.6215,2.3999047,,,,,1,,,,1.5779825E-5,1000,188.30171,-0.97900269,0