File: example/example12-ExperimentDataAnalysis/ppms/Peking/MT_0.csv
[Header]
; MPMS3 Data File (default extension .dat)
; Copyright (c) 2007, Quantum Design, Inc. All rights reserved.
TITLE,
FILEOPENTIME,3828684803.44002,04/27/2021,11:35 am
BYAPP,SQUID AC,0.9.1.0
INFO,MPMS3 Measurement Release 1.1.16 Build 316, MultiVu Release 2.2.1.73,APPNAME
INFO,0,MOMENT_UNITS
INFO,NTO,SAMPLE_MATERIAL
INFO,,SAMPLE_COMMENT
INFO,28.835,SAMPLE_MASS
INFO,,SAMPLE_VOLUME
INFO,,SAMPLE_MOLECULAR_WEIGHT
INFO,,SAMPLE_SIZE
INFO,,SAMPLE_SHAPE
INFO,Straw,SAMPLE_HOLDER
INFO,Standard,SAMPLE_HOLDER_DETAIL
INFO,55.27,SAMPLE_OFFSET
DATATYPE,COMMENT,1
DATATYPE,TIME,2
STARTUPAXIS,X,2
STARTUPAXIS,Y1,5
FIELDGROUP, VSM,2,3,4,5,6,8,9,10,11,14,15
FIELDGROUP, DC, 2,3,4,14,56,57,58,59,60,61,62,63,64,65,66,67,68,69
FIELDGROUP, AC, 2,3,4,11,16,17,18,19,20,21,22,23,24,25,26,27,28,29,30
STARTUPGROUP, All
[Data]
Comment,Time Stamp (sec),Temperature (K),Magnetic Field (Oe),Moment (emu),M. Std. Err. (emu),Transport Action,Averaging Time (sec),Frequency (Hz),Peak Amplitude (mm),Center Position (mm),Lockin Signal' (V),Lockin Signal (V),Range,M. Quad. Signal (emu),AC Moment (emu),AC M. Std Err. (emu),AC Phase (deg),AC Phase Std. Err. (deg),AC Susceptibility (emu/Oe),AC Suscept. Std Err. (emu/Oe),AC X' (emu/Oe),AC X' Std Err. (emu/Oe),AC X'' (emu/Oe),AC X'' Std Err. (emu/Oe),AC Drive (Oe),AC Frequency (Hz),AC Averaging Time (sec),AC Cycles,AC Range,AC Measure Type,AC Signal' (V),AC Signal'' (V),AC Trim Coil Ratio,AC Trim Coil Phase,Min. Temperature (K),Max. Temperature (K),Min. Field (Oe),Max. Field (Oe),Mass (grams),Motor Lag (deg),Pressure (Torr),Measure Count,Measurement Number,SQUID Status (code),Motor Status (code),Measure Status (code),Motor Current (amps),Motor Temp. (C),Temp. Status (code),Field Status (code),Chamber Status (code),Chamber Temp (K),Redirection State,Evercool Status,Average Temp (K),Rotation Angle (deg),Rotator state,DC Moment Fixed Ctr (emu),DC Moment Err Fixed Ctr (emu),DC Moment Free Ctr (emu),DC Moment Err Free Ctr (emu),DC Fixed Fit,DC Free Fit,DC Calculated Center (mm),DC Calculated Center Err (mm),DC Scan Length (mm),DC Scan Time (s),DC Number of Points,DC Squid Drift,DC Min V (V),DC Max V (V),DC Scans per Measure,Map 01,Map 02,Map 03,Map 04,Map 05,Map 06,Map 07,Map 08,Map 09,Map 10,Map 11,Map 12,Map 13,Map 14,Map 15,Map 16
,3828684816.14852,1.80010253190994,1000.05786132813,,,6,,,,31.7933628403348,,,100,,,,,,,,,,,,,,,,,,,,,,1.79942464828491,1.80119252204895,1000.05786132813,1000.05786132813,,,2.34817361831665,-99999999,1,0,0,0,0.013885498046875,29.8142719268799,1,1,1,1.80023837089539,0,2080379808,1.80018565654755,,,0.0312592337183484,0.00157557115988982,0.0314936875317314,0.00157604768325786,0.873739242553711,0.958420217037201,31.3462200164795,0.190861418843269,30,4,200,-0.00087032321607694,-1.2828608751297,0.216889157891274,1,,,,,,,,,,,,,,,,
,3828684859.13934,1.91666656732559,1000.05786132813,,,6,,,,31.7933628403348,,,100,,,,,,,,,,,,,,,,,,,,,,1.90065670013428,1.93104577064514,1000.05786132813,1000.05786132813,,,2.46642160415649,-99999999,1,0,0,0,0.0147247314453125,29.8142719268799,2,1,1,1.93267643451691,0,2080379712,1.91603909730911,,,0.0308152138346999,0.00155323199573021,0.0310472062795046,0.0015537045958929,0.873531877994537,0.958409011363983,31.3453960418701,0.190870568156242,30,4,200,-0.000836826278828084,-1.26274645328522,0.217022716999054,1,,,,,,,,,,,,,,,,
,3828684919.07639,2.11637473106384,1000.05786132813,,,6,,,,31.7933628403348,,,100,,,,,,,,,,,,,,,,,,,,,,2.10035753250122,2.1318826675415,1000.05786132813,1000.05786132813,,,2.60606122016907,-99999999,1,0,0,0,0.0147247314453125,29.8142719268799,2,1,1,2.13239192962646,0,2080379872,2.11588959693909,,,0.0302525549996804,0.00152491209516073,0.0304813329963553,0.00152538435589767,0.873325705528259,0.958446681499481,31.3445491790771,0.190863937139511,30,4,200,-0.000804604671429843,-1.24788689613342,0.216404005885124,1,,,,,,,,,,,,,,,,
,3828684979.12131,2.31635355949402,1000.05786132813,,,6,,,,31.7933628403348,,,100,,,,,,,,,,,,,,,,,,,,,,2.30005812644958,2.33184719085693,1000.05786132813,1000.05786132813,,,2.73443913459778,-99999999,1,0,0,0,0.013885498046875,29.8142719268799,2,1,1,2.33264899253845,0,2080379840,2.31603524684906,,,0.029754404223513,0.00149985800823275,0.0299807079232021,0.00150032416443288,0.873037397861481,0.958563566207886,31.3432350158691,0.19087079167366,30,4,200,-0.000767692748922855,-1.2237114906311,0.206154778599739,1,,,,,,,,,,,,,,,,
,3828685039.08538,2.5162718296051,1000.05786132813,,,6,,,,31.7933628403348,,,100,,,,,,,,,,,,,,,,,,,,,,2.50013780593872,2.53092741966248,1000.05786132813,1000.05786132813,,,2.85651874542236,-99999999,1,0,0,0,0.0147247314453125,29.8142719268799,2,1,1,2.53240585327148,0,2080379808,2.51579735279083,,,0.0293004210689931,0.00147699050036625,0.0295237984419146,0.00147745236466803,0.872948050498962,0.958669543266296,31.3427200317383,0.19087715446949,30,4,200,-0.000749443424865603,-1.20106887817383,0.207661494612694,1,,,,,,,,,,,,,,,,
,3828685099.05523,2.71628534793854,1000.05786132813,,,6,,,,31.7933628403348,,,100,,,,,,,,,,,,,,,,,,,,,,2.70080924034119,2.73121666908264,1000.05786132813,1000.05786132813,,,2.97272396087646,-99999999,1,0,0,0,0.014801025390625,29.8142719268799,2,1,1,2.73176145553589,0,2080379776,2.71586928367615,,,0.0288799533852445,0.00145583299731701,0.0291011830533273,0.00145630166084126,0.872747004032135,0.958697497844696,31.3418674468994,0.190887674689293,30,4,200,-0.00073028466431424,-1.1905425786972,0.198463752865791,1,,,,,,,,,,,,,,,,
,3828685159.23372,2.91648495197296,1000.05786132813,,,6,,,,31.7933628403348,,,100,,,,,,,,,,,,,,,,,,,,,,2.90057730674744,2.93117809295654,1000.05786132813,1000.05786132813,,,3.07904100418091,-99999999,1,0,0,0,0.0147247314453125,29.8142719268799,2,1,1,2.93239259719849,0,2080379872,2.91617619991302,,,0.0284913259639515,0.00143628578111455,0.0287102495032615,0.00143673772182698,0.872515022754669,0.958711802959442,31.3409461975098,0.19088289141655,30,4,200,-0.000720360490959138,-1.17011296749115,0.200628370046616,1,,,,,,,,,,,,,,,,
,3828685219.21136,3.11637783050537,1000.05786132813,,,6,,,,31.7933628403348,,,100,,,,,,,,,,,,,,,,,,,,,,3.10043621063232,3.13129472732544,1000.05786132813,1000.05786132813,,,3.1802933216095,-99999999,1,0,0,0,0.0147247314453125,29.8142719268799,2,1,1,3.13252711296082,0,2080379968,3.1161422252655,,,0.0281302141845664,0.00141810937604038,0.0283470875776804,0.00141856342268041,0.872363686561585,0.958722054958344,31.3403015136719,0.190898939967155,30,4,200,-0.000713548855856061,-1.16144239902496,0.20314659178257,1,,,,,,,,,,,,,,,,
,3828685279.24553,3.31647443771362,1000.05786132813,,,6,,,,31.7933628403348,,,100,,,,,,,,,,,,,,,,,,,,,,3.30050611495972,3.33133769035339,1000.05786132813,1000.05786132813,,,3.28035521507263,-99999999,1,0,0,0,0.0147247314453125,30.3030319213867,2,1,1,3.33244276046753,0,2080379840,3.31615767478943,,,0.0277898688134709,0.001400988573518,0.0280045815483013,0.00140142248156632,0.872162520885468,0.958743333816528,31.3395080566406,0.190888181328774,30,4,200,-0.000696238479577005,-1.14258015155792,0.19518980383873,1,,,,,,,,,,,,,,,,
,3828685339.51447,3.51713871955872,1000.05786132813,,,6,,,,31.7933628403348,,,100,,,,,,,,,,,,,,,,,,,,,,3.50072503089905,3.53222346305847,1000.05786132813,1000.05786132813,,,3.37286305427551,-99999999,1,0,0,0,0.0147247314453125,29.8142719268799,2,1,1,3.53355240821838,0,2080379776,3.51674818992615,,,0.0274658772357464,0.00138468335066697,0.027679062165734,0.00138513233333868,0.872003495693207,0.95874410867691,31.3388175964355,0.190916582942009,30,4,200,-0.000679930730257183,-1.1242493391037,0.198373213410378,1,,,,,,,,,,,,,,,,
,3828685399.23393,3.71635031700134,1000.05786132813,,,6,,,,31.7933628403348,,,100,,,,,,,,,,,,,,,,,,,,,,3.70020079612732,3.7317943572998,1000.05786132813,1000.05786132813,,,3.46127414703369,-99999999,1,0,0,0,0.0147247314453125,29.8142719268799,2,1,1,3.73249983787537,0,2080379808,3.71592109203339,,,0.0271602900288822,0.00136930500518338,0.0273714481662249,0.00136973658880734,0.871845841407776,0.958771646022797,31.338191986084,0.190903544425964,30,4,200,-0.000671969028189778,-1.11709308624268,0.191133111715317,1,,,,,,,,,,,,,,,,
,3828685459.40444,3.91690874099731,1000.05786132813,,,6,,,,31.7933628403348,,,100,,,,,,,,,,,,,,,,,,,,,,3.90049290657043,3.93195652961731,1000.05786132813,1000.05786132813,,,3.54407787322998,-99999999,1,0,0,0,0.0147247314453125,29.8142719268799,2,1,1,3.93332457542419,0,2080379904,3.91636297702789,,,0.0268672081414971,0.00135455239922033,0.0270768276502099,0.00135499268189058,0.87171733379364,0.958789229393005,31.3376312255859,0.190917432308197,30,4,200,-0.000669045781251043,-1.09959197044373,0.183981075882912,1,,,,,,,,,,,,,,,,
,3828685560.14913,4.00107097625732,1000.05786132813,,,6,,,,31.7933628403348,,,100,,,,,,,,,,,,,,,,,,,,,,3.99770140647888,4.00198459625244,1000.05786132813,1000.05786132813,,,3.57677435874939,-99999999,1,0,0,0,0.013885498046875,29.8142719268799,1,1,1,4.00089406967163,0,2080379840,4.00025041103363,,,0.0267475694655095,0.00134850135881911,0.0269556561902031,0.00134892668545688,0.87182754278183,0.958832085132599,31.3379974365234,0.190921247005463,30,4,200,-0.000618605350609869,-1.10075950622559,0.187870696187019,1,,,,,,,,,,,,,,,,
,3828685617.9408,6.22054409980774,1000.05786132813,,,6,,,,31.7933628403348,,,100,,,,,,,,,,,,,,,,,,,,,,6.00009918212891,6.42877244949341,1000.05786132813,1000.05786132813,,,4.27296590805054,-99999999,1,0,0,0,0.0147247314453125,30.3030319213867,6,1,1,6.44098901748657,0,2080379904,6.2139865398407,,,0.0242012896593153,0.00122036198269073,0.0243943619316093,0.0012207658565247,0.870365738868713,0.958576142787933,31.33251953125,0.190947368741035,30,4,200,-0.000924937252420932,-0.999804317951202,0.170947939157486,1,,,,,,,,,,,,,,,,
,3828685703.18798,10.2223620414734,1000.05786132813,,,6,,,,31.7933628403348,,,100,,,,,,,,,,,,,,,,,,,,,,10.0047740936279,10.4308500289917,1000.05786132813,1000.05786132813,,,4.9606876373291,-99999999,1,0,0,0,0.0147247314453125,29.8142719268799,6,1,1,10.4399499893188,0,2080379904,10.2179599761963,,,0.0209494815407894,0.00105650405085517,0.0211192814986923,0.00105686322176764,0.869534969329834,0.958757698535919,31.3290004730225,0.190960347652435,30,4,200,-0.000759033602662385,-0.85999459028244,0.146788388490677,1,,,,,,,,,,,,,,,,
,3828685787.46612,14.2405529022217,1000.05786132813,,,6,,,,31.7983639784801,,,100,,,,,,,,,,,,,,,,,,,,,,14.0094928741455,14.452543258667,1000.05786132813,1000.05786132813,,,5.64821815490723,-99999999,1,0,0,0,0.0147247314453125,29.8142719268799,6,1,1,14.4716129302978,0,2080379712,14.2336850166321,,,0.0184868403177299,0.000932459351774314,0.018639502144017,0.000932765105500285,0.868338584899902,0.958852887153625,31.3290958404541,0.191000327467918,30,4,200,-0.000650411820970476,-0.769138216972351,0.132696077227592,1,,,,,,,,,,,,,,,,
,3828685868.37029,18.2467746734619,1000.05786132813,,,6,,,,31.7983639784801,,,100,,,,,,,,,,,,,,,,,,,,,,18.0152626037598,18.4662628173828,1000.05786132813,1000.05786132813,,,5.93864488601685,-99999999,1,0,0,0,0.0147247314453125,29.8142719268799,2,1,1,18.4782867431641,0,2080379936,18.2342926025391,,,0.0165484622582583,0.000834646075966638,0.0166841343022267,0.000834914933292511,0.868726134300232,0.958821773529053,31.3306655883789,0.190997943282127,30,4,200,-0.000574892503209412,-0.685370028018951,0.114265620708466,1,,,,,,,,,,,,,,,,
,3828685953.28543,22.3529806137085,1000.05786132813,,,6,,,,31.8033671521862,,,100,,,,,,,,,,,,,,,,,,,,,,22.1216239929199,22.5597305297852,1000.05786132813,1000.05786132813,,,6.12195301055908,-99999999,1,0,0,0,0.0147247314453125,30.3030319213867,2,1,1,22.5843372344971,0,2080379872,22.3404949188232,,,0.0149206113085574,0.000752556933932921,0.0150435239414297,0.000752810892370013,0.868588328361511,0.95894867181778,31.3349647521973,0.190999627113342,30,4,200,-0.000499086920171976,-0.612101554870605,0.0999472811818123,1,,,,,,,,,,,,,,,,
,3828686033.67453,26.2353038787842,1000.05786132813,,,6,,,,31.8033671521862,,,100,,,,,,,,,,,,,,,,,,,,,,26.0161228179932,26.4600791931152,1000.05786132813,1000.05786132813,,,6.27330303192139,-99999999,1,0,0,0,0.0147247314453125,29.8142719268799,2,1,1,26.4699516296387,0,2080379968,26.2358936309814,,,0.0136461256287307,0.00068817113601598,0.0137563756165097,0.00068839764647737,0.869720995426178,0.958993017673492,31.339427947998,0.190958619117737,30,4,200,-0.000460675393696874,-0.561649799346924,0.09043999761343,1,,,,,,,,,,,,,,,,
,3828686116.12003,30.2388076782227,1000.05786132813,,,6,,,,31.8033671521862,,,100,,,,,,,,,,,,,,,,,,,,,,30.0016460418701,30.455530166626,1000.05786132813,1000.05786132813,,,6.38572406768799,-99999999,1,0,0,0,0.0147247314453125,29.8142719268799,2,1,1,30.4759693145752,0,2080379744,30.2302473068237,,,0.0125457725594687,0.000632544134534627,0.0126443991594499,0.000632749280184522,0.87135910987854,0.959099352359772,31.3457775115967,0.190923854708672,30,4,200,-0.000412632944062352,-0.516982913017273,0.0831970721483231,1,,,,,,,,,,,,,,,,
,3828686198.43585,34.2421913146973,1000.05786132813,,,6,,,,31.808367555556,,,100,,,,,,,,,,,,,,,,,,,,,,34.0043754577637,34.4637145996094,1000.05786132813,1000.05786132813,,,6.50382089614868,-99999999,1,0,0,0,0.014801025390625,30.3030319213867,2,1,1,34.4800071716309,0,2080379872,34.2321136474609,,,0.0116091376273159,0.000585272513729876,0.0116993927952593,0.000585457072716191,0.871982157230377,0.95919942855835,31.3531112670898,0.190908774733543,30,4,200,-0.000377726042643189,-0.477875918149948,0.0782247707247734,1,,,,,,,,,,,,,,,,
,3828686282.97359,38.3546085357666,1000.05786132813,,,6,,,,31.8133753563267,,,100,,,,,,,,,,,,,,,,,,,,,,38.1241226196289,38.5711708068848,1000.05786132813,1000.05786132813,,,6.61005973815918,-99999999,1,0,0,0,0.013885498046875,30.7917900085449,2,1,1,38.5850944519043,0,2080379904,38.346097946167,,,0.0107803897462771,0.00054341865144979,0.0108628696618446,0.000543592487146001,0.873014748096466,0.9593625664711,31.3620071411133,0.190883740782738,30,4,200,-0.000349161244230345,-0.442490875720978,0.0745212510228157,1,,,,,,,,,,,,,,,,
,3828686362.50472,42.2418613433838,1000.05786132813,,,6,,,,31.8133753563267,,,100,,,,,,,,,,,,,,,,,,,,,,42.0072631835937,42.4617347717285,1000.05786132813,1000.05786132813,,,6.71074295043945,-99999999,1,0,0,0,0.0147247314453125,29.8142719268799,2,1,1,42.4764595031738,0,2080379712,42.2353660583496,,,0.0101122725201038,0.00050960147650345,0.0101867254788283,0.000509755505659855,0.87514340877533,0.959457516670227,31.3703536987305,0.19082672894001,30,4,200,-0.000327880930854008,-0.412478119134903,0.0730287358164787,1,,,,,,,,,,,,,,,,
,3828686444.52182,46.2407512664795,1000.05786132813,,,6,,,,31.8183777559675,,,100,,,,,,,,,,,,,,,,,,,,,,46.0066528320313,46.4475784301758,1000.05786132813,1000.05786132813,,,6.74368238449097,-99999999,1,0,0,0,0.0147247314453125,29.8142719268799,2,1,1,46.4748497009277,0,2080379872,46.2319435119629,,,0.00950473457334948,0.000478904061295002,0.0095730214919799,0.0004790418089255,0.876481235027313,0.959618508815765,31.3804798126221,0.190784707665443,30,4,200,-0.000310731265926734,-0.395402878522873,0.0614632479846478,1,,,,,,,,,,,,,,,,
,3828686528.54196,50.3583850860596,1000.05786132813,,,6,,,,31.8233823542841,,,100,,,,,,,,,,,,,,,,,,,,,,50.119701385498,50.5657386779785,1000.05786132813,1000.05786132813,,,6.81371641159058,-99999999,1,0,0,0,0.014801025390625,29.8142719268799,2,1,1,50.5970687866211,0,2080379936,50.342663192749,,,0.00895143605433881,0.000450937592630802,0.00901405403932928,0.000451067656661202,0.87804764509201,0.959779977798462,31.391487121582,0.190756484866142,30,4,200,-0.000280785781797022,-0.369252622127533,0.0615076087415218,1,,,,,,,,,,,,,,,,
,3828686610.15661,54.3523139953613,1000.05786132813,,,6,,,,31.8283873029654,,,100,,,,,,,,,,,,,,,,,,,,,,54.1167106628418,54.5243530273438,1000.05786132813,1000.05786132813,,,6.88793039321899,-99999999,1,0,0,0,0.0147247314453125,29.8142719268799,2,1,1,54.5879173278809,0,2080379808,54.3208550347222,,,0.00848123680237518,0.000427173059900022,0.00853891251035945,0.000427288184996579,0.879528403282166,0.959966599941254,31.4021434783936,0.190716415643692,30,4,200,-0.000267069903202355,-0.345803618431091,0.0627659559249878,1,,,,,,,,,,,,,,,,
,3828686695.59844,58.5496425628662,1000.05786132813,,,6,,,,31.8333967802708,,,100,,,,,,,,,,,,,,,,,,,,,,58.3162879943848,58.7580528259277,1000.05786132813,1000.05786132813,,,6.94673585891724,-99999999,1,0,0,0,0.014801025390625,29.8142719268799,2,1,1,58.7829971313477,0,2080379840,58.5408081054687,,,0.00804163765621693,0.000404944437964507,0.00809467247514781,0.000405055401792242,0.881307184696198,0.960148811340332,31.4139957427978,0.190677344799042,30,4,200,-0.000256241241004318,-0.33447653055191,0.0533798299729824,1,,,,,,,,,,,,,,,,
,3828686770.95886,62.2429256439209,1000.05786132813,,,6,,,,31.8333967802708,,,100,,,,,,,,,,,,,,,,,,,,,,62.0078239440918,62.4589958190918,1000.05786132813,1000.05786132813,,,6.9888768196106,-99999999,1,0,0,0,0.0147247314453125,30.3030319213867,2,1,1,62.47802734375,0,2080379904,62.2350975036621,,,0.00769591101338209,0.000387410208140143,0.0077442012716579,0.000387515391467508,0.88401472568512,0.960311114788055,31.4245948791504,0.190614193677902,30,4,200,-0.000250310200499371,-0.315102487802505,0.0564350001513958,1,,,,,,,,,,,,,,,,
,3828686852.24135,66.2395896911621,1000.05786132813,,,6,,,,31.8388675676772,,,100,,,,,,,,,,,,,,,,,,,,,,66.0043258666992,66.4587326049805,1000.05786132813,1000.05786132813,,,7.0212025642395,-99999999,1,0,0,0,0.0147247314453125,29.8142719268799,2,1,1,66.474853515625,0,2080379872,66.2319221496582,,,0.00735283517129318,0.000370064482216946,0.00739729080975791,0.000370153936351885,0.88575941324234,0.960461556911469,31.4368209838867,0.190581157803535,30,4,200,-0.000239351953496225,-0.306790351867676,0.0485619679093361,1,,,,,,,,,,,,,,,,
,3828686933.5185,70.2390937805176,1000.05786132813,,,6,,,,31.8439885727972,,,100,,,,,,,,,,,,,,,,,,,,,,70.0100021362305,70.4518508911133,1000.05786132813,1000.05786132813,,,7.06141710281372,-99999999,1,0,0,0,0.0147247314453125,29.8142719268799,2,1,1,70.4681854248047,0,2080379744,70.2338447570801,,,0.00704113620788829,0.000354299294366171,0.00708222583955218,0.000354386113015333,0.887667536735535,0.960626065731049,31.4493579864502,0.190540120005608,30,4,200,-0.000225152980419807,-0.288630962371826,0.0520564951002598,1,,,,,,,,,,,,,,,,
,3828687019.57164,74.4728317260742,1000.05786132813,,,6,,,,31.8544845165963,,,100,,,,,,,,,,,,,,,,,,,,,,74.2418212890625,74.6904525756836,1000.05786132813,1000.05786132813,,,7.10078573226929,-99999999,1,0,0,0,0.0147247314453125,29.8142719268799,2,1,1,74.7038421630859,0,2080379872,74.4630821228027,,,0.00673616019819812,0.000338917846883118,0.00677465655594229,0.00033899274585762,0.888592660427094,0.960848987102509,31.463228225708,0.190523236989975,30,4,200,-0.000210384852834977,-0.281631022691727,0.0446697473526001,1,,,,,,,,,,,,,,,,
,3828687098.18404,78.3621406555176,1000.05786132813,,,6,,,,31.8594862962095,,,100,,,,,,,,,,,,,,,,,,,,,,78.1245574951172,78.5836944580078,1000.05786132813,1000.05786132813,,,7.09905338287353,-99999999,1,0,0,0,0.014801025390625,29.8142719268799,2,1,1,78.599723815918,0,2080379968,78.3525291442871,,,0.00648225746285002,0.00032607009103759,0.00651782598619656,0.000326139808597563,0.890596270561218,0.960965573787689,31.4761295318604,0.190472215414047,30,4,200,-0.00023200549185276,-0.265201061964035,0.0388895235955715,1,,,,,,,,,,,,,,,,
,3828687179.23172,82.3641242980957,1000.05786132813,,,6,,,,31.8645558411016,,,100,,,,,,,,,,,,,,,,,,,,,,82.1385269165039,82.5755081176758,1000.05786132813,1000.05786132813,,,7.13658332824707,-99999999,1,0,0,0,0.0147247314453125,29.8142719268799,2,1,1,82.5897216796875,0,2080379904,82.3557693481445,,,0.00624273773623834,0.000313945644717061,0.00627545156095103,0.000314009477907621,0.892809092998505,0.961158692836761,31.4898147583008,0.190430015325546,30,4,200,-0.000196762513951398,-0.26027524471283,0.0427386276423931,1,,,,,,,,,,,,,,,,
,3828687257.54808,86.2346305847168,1000.05786132813,,,6,,,,31.8695675617909,,,100,,,,,,,,,,,,,,,,,,,,,,86.0167694091797,86.4572143554687,1000.05786132813,1000.05786132813,,,7.19346809387207,-99999999,1,0,0,0,0.0147247314453125,29.8142719268799,2,1,1,86.467041015625,0,2080379904,86.2372428894043,,,0.00603545551250337,0.000303452718048797,0.00606569977953323,0.000303511351274459,0.894921898841858,0.961387395858765,31.5030384063721,0.190366595983505,30,4,200,-0.000220444650040008,-0.245432645082474,0.0375831164419651,1,,,,,,,,,,,,,,,,
,3828687340.61345,90.3638801574707,1000.05786132813,,,6,,,,31.8795984949879,,,100,,,,,,,,,,,,,,,,,,,,,,90.1283874511719,90.5869598388672,1000.05786132813,1000.05786132813,,,7.18422651290894,-99999999,1,0,0,0,0.013885498046875,29.8142719268799,2,1,1,90.5993728637695,0,2080380032,90.3508369445801,,,0.00582313422399673,0.00029274189467666,0.00585169000279246,0.000292801075279728,0.896074891090393,0.961547017097473,31.5174598693848,0.190356612205505,30,4,200,-0.000208849683986045,-0.241446390748024,0.0418213307857513,1,,,,,,,,,,,,,,,,
,3828687420.47801,94.3664741516113,1000.05786132813,,,6,,,,31.8851089476502,,,100,,,,,,,,,,,,,,,,,,,,,,94.1279220581055,94.5931396484375,1000.05786132813,1000.05786132813,,,7.18568897247314,-99999999,1,0,0,0,0.013885498046875,29.8142719268799,2,1,1,94.6050262451172,0,2080379968,94.3610496520996,,,0.00563937397528976,0.000283440681553649,0.00566572542379666,0.000283493695875361,0.898216128349304,0.961748123168945,31.5313262939453,0.190314829349518,30,4,200,-0.00017679829034023,-0.227369785308838,0.0368926972150803,1,,,,,,,,,,,,,,,,
,3828687501.23721,98.3484153747559,1000.05786132813,,,6,,,,31.8951402255325,,,100,,,,,,,,,,,,,,,,,,,,,,98.1151580810547,98.5670166015625,1000.05786132813,1000.05786132813,,,7.22959613800049,-99999999,1,0,0,0,0.013885498046875,29.8142719268799,2,1,1,98.581672668457,0,2080379808,98.3448852539063,,,0.00546516031061424,0.000274649255672591,0.0054899964715003,0.000274698022732823,0.899473428726196,0.962016642093658,31.5460395812988,0.190282359719276,30,4,200,-0.000172803804161958,-0.224509313702583,0.0315548107028007,1,,,,,,,,,,,,,,,,
,3828687581.51484,102.362342834473,1000.05786132813,,,6,,,,31.9002196696363,,,100,,,,,,,,,,,,,,,,,,,,,,102.119644165039,102.586402893066,1000.05786132813,1000.05786132813,,,7.23739814758301,-99999999,1,0,0,0,0.013885498046875,31.2805480957031,2,1,1,102.605041503906,0,2080379872,102.356288909912,,,0.00529906781908984,0.000266237764228772,0.00532179799620937,0.000266280863859072,0.901891112327576,0.962130427360535,31.5607452392578,0.190248981118202,30,4,200,-0.00019006738148164,-0.22180201113224,0.0367271043360233,1,,,,,,,,,,,,,,,,
,3828687662.54261,106.386226654053,1000.05786132813,,,6,,,,31.9102481916977,,,100,,,,,,,,,,,,,,,,,,,,,,106.1318359375,106.603080749512,1000.05786132813,1000.05786132813,,,7.25270366668701,-99999999,1,0,0,0,0.013885498046875,29.8142719268799,2,1,1,106.640617370605,0,2080379840,106.362715911865,,,0.00514397695316597,0.00025840999387099,0.00516539239775457,0.000258452415579721,0.903298556804657,0.962405622005463,31.5760612487793,0.190218865871429,30,4,200,-0.000184181029908359,-0.208594262599945,0.0322249121963978,1,,,,,,,,,,,,,,,,
,3828687740.58684,110.242385864258,1000.05786132813,,,6,,,,31.9152594666757,,,100,,,,,,,,,,,,,,,,,,,,,,110.005165100098,110.457618713379,1000.05786132813,1000.05786132813,,,7.27751207351685,-99999999,1,0,0,0,0.013885498046875,29.8142719268799,2,1,1,110.479606628418,0,2080379904,110.236609649658,,,0.00500720164194722,0.000251474869413949,0.00502677294328562,0.000251513283729868,0.90594482421875,0.962740898132324,31.5913181304932,0.190172031521797,30,4,200,-0.0001637309032958,-0.206756353378296,0.0276168212294579,1,,,,,,,,,,,,,,,,
,3828687823.00431,114.367141723633,1000.05786132813,,,6,,,,31.9257311002927,,,100,,,,,,,,,,,,,,,,,,,,,,114.119277954102,114.587013244629,1000.05786132813,1000.05786132813,,,7.29711484909058,-99999999,1,0,0,0,0.0147247314453125,30.3030319213867,2,1,1,114.605339050293,0,2080379840,114.352789306641,,,0.0048628882369889,0.000244196498387989,0.00488130203161511,0.000244233530164678,0.907274842262268,0.962871015071869,31.6070232391357,0.190145343542099,30,4,200,-0.000152016058564186,-0.204829066991806,0.0331382527947426,1,,,,,,,,,,,,,,,,
,3828687903.34767,118.369441986084,1000.05786132813,,,6,,,,31.9357445167964,,,100,,,,,,,,,,,,,,,,,,,,,,118.122840881348,118.602867126465,1000.05786132813,1000.05786132813,,,7.3260326385498,-99999999,1,0,0,0,0.013885498046875,30.3030319213867,2,1,1,118.61604309082,0,2080379872,118.357390594482,,,0.00473456800715697,0.000237717965909782,0.00475183666549949,0.00023775336578986,0.908851861953735,0.963147222995758,31.6230278015137,0.190121650695801,30,4,200,-0.000150015679537319,-0.192370384931564,0.0290758721530437,1,,,,,,,,,,,,,,,,
,3828687983.39757,122.351909637451,1000.05786132813,,,6,,,,31.9457800178461,,,100,,,,,,,,,,,,,,,,,,,,,,122.114295959473,122.576782226563,1000.05786132813,1000.05786132813,,,7.33712387084961,-99999999,1,0,0,0,0.013885498046875,29.8142719268799,2,1,1,122.58952331543,0,2080379872,122.34928894043,,,0.00461407801075072,0.000231633593332542,0.00463019495066397,0.000231664356740113,0.910493195056915,0.963467419147491,31.6392574310303,0.190090015530586,30,4,200,-0.000147096885484643,-0.191021531820297,0.0247011780738831,1,,,,,,,,,,,,,,,,
,3828688065.69054,126.451049804687,1000.05786132813,,,6,,,,31.9557884886377,,,100,,,,,,,,,,,,,,,,,,,,,,126.212562561035,126.679595947266,1000.05786132813,1000.05786132813,,,7.35558366775513,-99999999,1,0,0,0,0.013885498046875,30.3030319213867,2,1,1,126.68953704834,0,2080379936,126.444758605957,,,0.00449666234317667,0.000225702179515362,0.00451164680753147,0.00022573104693088,0.912328779697418,0.963706493377686,31.656421661377,0.190050676465034,30,4,200,-0.000143920682603493,-0.189852476119995,0.0308155138045549,1,,,,,,,,,,,,,,,,
,3828688143.89619,130.36710357666,1000.05786132813,,,6,,,,31.9658309555075,,,100,,,,,,,,,,,,,,,,,,,,,,130.132095336914,130.587936401367,1000.05786132813,1000.05786132813,,,7.37687921524048,-99999999,1,0,0,0,0.013885498046875,29.8142719268799,2,1,1,130.602111816406,0,2080379776,130.362080383301,,,0.00438915232608838,0.000220274528062188,0.00440317973124032,0.000220302501436956,0.91395765542984,0.963912844657898,31.672830581665,0.190020695328712,30,4,200,-0.000140819945954718,-0.177945151925087,0.0271609351038933,1,,,,,,,,,,,,,,,,
,3828688224.43018,134.363540649414,1000.05786132813,,,6,,,,31.975912536315,,,100,,,,,,,,,,,,,,,,,,,,,,134.119644165039,134.587753295898,1000.05786132813,1000.05786132813,,,7.3891921043396,-99999999,1,0,0,0,0.013885498046875,30.3030319213867,2,1,1,134.611511230469,0,2080379904,134.354949951172,,,0.00428356984976195,0.000214943664075344,0.00429662473431868,0.000214969675431494,0.915697634220123,0.964119791984558,31.6897354125977,0.190001294016838,30,4,200,-0.000136738555738702,-0.17703016102314,0.0230794977396727,1,,,,,,,,,,,,,,,,
,3828688303.93699,138.347213745117,1000.05786132813,,,6,,,,31.9859381672363,,,100,,,,,,,,,,,,,,,,,,,,,,138.117340087891,138.558197021484,1000.05786132813,1000.05786132813,,,7.38573932647705,-99999999,1,0,0,0,0.013885498046875,29.3255138397217,2,1,1,138.577087402344,0,2080379680,138.335679626465,,,0.00418478222362498,0.000209953918605689,0.00419689215248004,0.000209977842836539,0.917553246021271,0.964383780956268,31.7070007324219,0.189963445067406,30,4,200,-0.000133077701320872,-0.176266238093376,0.0296891499310732,1,,,,,,,,,,,,,,,,
,3828688384.50554,142.357849121094,1000.05786132813,,,6,,,,31.9971956619903,,,100,,,,,,,,,,,,,,,,,,,,,,142.123382568359,142.572784423828,1000.05786132813,1000.05786132813,,,7.44910955429077,-99999999,1,0,0,0,0.013885498046875,29.8142719268799,2,1,1,142.596343994141,0,2080379904,142.346415710449,,,0.00408942286334991,0.000205141398335219,0.00410071716241375,0.000205164043136966,0.919227242469788,0.964651107788086,31.7247161865234,0.189952209591866,30,4,200,-0.000131795241031796,-0.16474960744381,0.026207260787487,1,,,,,,,,,,,,,,,,
,3828688464.80243,146.35604095459,1000.05786132813,,,6,,,,32.0092977962829,,,100,,,,,,,,,,,,,,,,,,,,,,146.124649047852,146.571090698242,1000.05786132813,1000.05786132813,,,7.43246507644653,-99999999,1,0,0,0,0.013885498046875,29.3255138397217,2,1,1,146.587432861328,0,2080380000,146.347593688965,,,0.00399902796559048,0.00020058314885211,0.00400958468080397,0.000200602731660098,0.920698225498199,0.964922487735748,31.7424545288086,0.18992868065834,30,4,200,-0.000126784027088434,-0.164246872067451,0.0224586520344019,1,,,,,,,,,,,,,,,,
,3828688545.21143,150.361251831055,1000.05786132813,,,6,,,,32.021584781074,,,100,,,,,,,,,,,,,,,,,,,,,,150.134994506836,150.597946166992,1000.05786132813,1000.05786132813,,,7.46762371063232,-99999999,1,0,0,0,0.013885498046875,29.8142719268799,2,1,1,150.597946166992,0,2080379872,150.362557983398,,,0.0039124175691641,0.000196215684447186,0.00392233681807977,0.000196235716839763,0.922193944454193,0.965194940567017,31.7605037689209,0.189896106719971,30,4,200,-0.000124173238873482,-0.163808643817902,0.0293182451277971,1,,,,,,,,,,,,,,,,
,3828688625.39778,154.363830566406,1000.05786132813,,,6,,,,32.0342512021979,,,100,,,,,,,,,,,,,,,,,,,,,,154.120315551758,154.583404541016,1000.05786132813,1000.05786132813,,,7.45713138580322,-99999999,1,0,0,0,0.013885498046875,29.8142719268799,2,1,1,154.607345581055,0,2080379872,154.352886962891,,,0.00382967076035782,0.000192044096309793,0.00383896453316576,0.000192062721404483,0.923651337623596,0.965478479862213,31.7787628173828,0.189860761165619,30,4,200,-0.000123811274534091,-0.152559369802475,0.0261426344513893,1,,,,,,,,,,,,,,,,
,3828688705.45114,158.356430053711,1000.05786132813,,,6,,,,32.0472163269486,,,100,,,,,,,,,,,,,,,,,,,,,,158.126312255859,158.575103759766,1000.05786132813,1000.05786132813,,,7.46438980102539,-99999999,1,0,0,0,0.013885498046875,29.8142719268799,2,1,1,158.586547851562,0,2080379904,158.34934387207,,,0.00375057778897436,0.00018805770399967,0.00375927451145267,0.000188073892030655,0.925058901309967,0.965775787830353,31.7970485687256,0.189859509468079,30,4,200,-0.000121556695376057,-0.152321085333824,0.0226568654179573,1,,,,,,,,,,,,,,,,
,3828688786.06949,162.368446350098,1000.05786132813,,,6,,,,32.0606280500824,,,100,,,,,,,,,,,,,,,,,,,,,,162.12956237793,162.595184326172,1000.05786132813,1000.05786132813,,,7.48108720779419,-99999999,1,0,0,0,0.013885498046875,30.3030319213867,2,1,1,162.617599487305,0,2080379744,162.361781311035,,,0.00367419938171509,0.000184208598512826,0.00368238520018075,0.000184225257039362,0.926467597484589,0.966073632240295,31.8158397674561,0.189824908971786,30,4,200,-0.000117237243102863,-0.152168482542038,0.0192031562328339,1,,,,,,,,,,,,,,,,
,3828688866.27612,166.361282348633,1000.05786132813,,,6,,,,32.074244869746,,,100,,,,,,,,,,,,,,,,,,,,,,166.125473022461,166.576263427734,1000.05786132813,1000.05786132813,,,7.50367784500122,-99999999,1,0,0,0,0.013885498046875,30.3030319213867,2,1,1,166.597091674805,0,2080379776,166.351731872559,,,0.00360123005743976,0.000180531617050515,0.00360892127045087,0.000180548014487802,0.92787629365921,0.966391384601593,31.8347663879395,0.189818888902664,30,4,200,-0.000116106260975357,-0.152068644762039,0.0264068637043238,1,,,,,,,,,,,,,,,,
,3828688946.25598,170.352020263672,1000.05786132813,,,6,,,,32.0882547836534,,,100,,,,,,,,,,,,,,,,,,,,,,170.118698120117,170.565582275391,1000.05786132813,1000.05786132813,,,7.49312734603882,-99999999,1,0,0,0,0.0139617919921875,29.8142719268799,2,1,1,170.585342407227,0,2080379904,170.343843078613,,,0.00353143238505666,0.000177015482695316,0.00353859467406953,0.000177028060910346,0.929228663444519,0.966676473617554,31.8539371490479,0.189803659915924,30,4,200,-0.000114053291326854,-0.141201332211494,0.0234412252902985,1,,,,,,,,,,,,,,,,
,3828689027.07931,174.375999450684,1000.05786132813,,,6,,,,32.1054424725364,,,100,,,,,,,,,,,,,,,,,,,,,,174.136108398438,174.601745605469,1000.05786132813,1000.05786132813,,,7.51115608215332,-99999999,1,0,0,0,0.013885498046875,29.8142719268799,2,1,1,174.61589050293,0,2080379712,174.369805908203,,,0.00346409489080191,0.000173630448341891,0.00347096998012899,0.000173642801322214,0.930014371871948,0.967040777206421,31.8737106323242,0.189797818660736,30,4,200,-0.000111763074528426,-0.141299307346344,0.0201719477772713,1,,,,,,,,,,,,,,,,
,3828689107.00451,178.375427246094,1000.05786132813,,,6,,,,32.1223687764424,,,100,,,,,,,,,,,,,,,,,,,,,,178.136871337891,178.595352172852,1000.05786132813,1000.05786132813,,,7.5317063331604,-99999999,1,0,0,0,0.0147247314453125,29.8142719268799,2,1,1,178.613983154297,0,2080379936,178.372018432617,,,0.00339850976340776,0.000170335255860952,0.00340513561652616,0.000170348057351634,0.930679142475128,0.96727043390274,31.8929958343506,0.189787715673447,30,4,200,-0.000109059539681766,-0.141381368041039,0.0170056950300932,1,,,,,,,,,,,,,,,,
,3828689187.30139,182.360153198242,1000.05786132813,,,6,,,,32.1374384958407,,,100,,,,,,,,,,,,,,,,,,,,,,182.126617431641,182.593688964844,1000.05786132813,1000.05786132813,,,7.55607891082764,-99999999,1,0,0,0,0.014801025390625,30.3030319213867,2,1,1,182.593688964844,0,2080379936,182.363397216797,,,0.00333619583190845,0.000167197836714241,0.00334241261494908,0.000167208911422106,0.931906580924988,0.967503786087036,31.9128189086914,0.189770847558975,30,4,200,-0.000106195802800357,-0.141536191105843,0.024480152875185,1,,,,,,,,,,,,,,,,
,3828689267.41021,186.363227844238,1000.05786132813,,,6,,,,32.1527562930588,,,100,,,,,,,,,,,,,,,,,,,,,,186.128967285156,186.582611083984,1000.05786132813,1000.05786132813,,,7.56686401367187,-99999999,1,0,0,0,0.0147247314453125,30.3030319213867,2,1,1,186.59748840332,0,2080379968,186.354469299316,,,0.00327631647713152,0.000164185830750507,0.00328222474828816,0.000164197354084286,0.932903230190277,0.967618644237518,31.932186126709,0.189738407731056,30,4,200,-0.000106571693322621,-0.130881577730179,0.0217612069100142,1,,,,,,,,,,,,,,,,
,3828689347.1344,190.358238220215,1000.05786132813,,,6,,,,32.1682666053613,,,100,,,,,,,,,,,,,,,,,,,,,,190.123870849609,190.576034545898,1000.05786132813,1000.05786132813,,,7.55048942565918,-99999999,1,0,0,0,0.013885498046875,30.3030319213867,2,1,1,190.59260559082,0,2080379872,190.347364807129,,,0.00321928073633561,0.000161316009052406,0.00322483957245881,0.000161325584275839,0.933978676795959,0.967812657356262,31.9518890380859,0.189734563231468,30,4,200,-0.000102765880001243,-0.131122648715973,0.0188097283244133,1,,,,,,,,,,,,,,,,
,3828689427.85523,194.355072021484,1000.05786132813,,,6,,,,32.1844254576117,,,100,,,,,,,,,,,,,,,,,,,,,,194.125,194.574066162109,1000.05786132813,1000.05786132813,,,7.57680559158325,-99999999,1,0,0,0,0.013885498046875,30.7917900085449,2,1,1,194.596313476562,0,2080379904,194.350326538086,,,0.00316299373914996,0.000158482352706492,0.00316822156381987,0.000158491729801403,0.935240030288696,0.968100249767303,31.9728832244873,0.189697951078415,30,4,200,-0.000102237507235259,-0.131435051560402,0.0158618446439505,1,,,,,,,,,,,,,,,,
,3828689507.86769,198.357452392578,1000.05786132813,,,6,,,,32.2007771984128,,,100,,,,,,,,,,,,,,,,,,,,,,198.128143310547,198.575317382813,1000.05786132813,1000.05786132813,,,7.60261297225952,-99999999,1,0,0,0,0.013885498046875,30.3030319213867,2,1,1,198.586761474609,0,2080379936,198.350160217285,,,0.00310970356238434,0.000155801573597977,0.00311464762689551,0.000155810996211017,0.936300873756409,0.968234717845917,31.9935131072998,0.189700171351433,30,4,200,-0.000100675220892299,-0.131846874952316,0.0235838796943426,1,,,,,,,,,,,,,,,,
,3828689588.05796,202.359436035156,1000.05786132813,,,6,,,,32.2174822346731,,,100,,,,,,,,,,,,,,,,,,,,,,202.122985839844,202.581085205078,1000.05786132813,1000.05786132813,,,7.59942007064819,-99999999,1,0,0,0,0.0147247314453125,30.3030319213867,2,1,1,202.595886230469,0,2080379968,202.351637268066,,,0.00305750062190824,0.00015317548582284,0.00306213894358331,0.000153183386257241,0.937397599220276,0.96841436624527,32.0145645141602,0.189700320363045,30,4,200,-9.72890047705732E-5,-0.121283255517483,0.0210873670876026,1,,,,,,,,,,,,,,,,
,3828689668.41372,206.355155944824,1000.05786132813,,,6,,,,32.2345434152316,,,100,,,,,,,,,,,,,,,,,,,,,,206.125061035156,206.573455810547,1000.05786132813,1000.05786132813,,,7.61974382400513,-99999999,1,0,0,0,0.013885498046875,30.3030319213867,2,1,1,206.585250854492,0,2080379808,206.345945739746,,,0.00300726660613136,0.000150649370252071,0.00301165689608021,0.000150657221888017,0.938404560089111,0.968578636646271,32.0356597900391,0.189672186970711,30,4,200,-9.54308852669783E-5,-0.121655263006687,0.0183436200022697,1,,,,,,,,,,,,,,,,
,3828689748.59436,210.364585876465,1000.05786132813,,,6,,,,32.2518843131323,,,100,,,,,,,,,,,,,,,,,,,,,,210.122283935547,210.586013793945,1000.05786132813,1000.05786132813,,,7.65320062637329,-99999999,1,0,0,0,0.013885498046875,29.8142719268799,2,1,1,210.606887817383,0,2080379968,210.354620361328,,,0.00295950595106189,0.000148249210184382,0.00296368239488006,0.000148256941251871,0.939238607883453,0.968660056591034,32.0564575195313,0.189667239785194,30,4,200,-8.86961643118411E-5,-0.122078061103821,0.0157488491386175,1,,,,,,,,,,,,,,,,
,3828689828.99471,214.367294311523,1000.05786132813,,,6,,,,32.2695431133682,,,100,,,,,,,,,,,,,,,,,,,,,,214.135696411133,214.58528137207,1000.05786132813,1000.05786132813,,,7.66487121582031,-99999999,1,0,0,0,0.013885498046875,29.8142719268799,2,1,1,214.598892211914,0,2080379904,214.357943725586,,,0.00291162530346216,0.000145842086847863,0.002915560261204,0.00014584892805392,0.940219044685364,0.968816697597504,32.0780563354492,0.189662724733353,30,4,200,-0.000111319270217791,-0.122567482292652,0.0129448296502233,1,,,,,,,,,,,,,,,,
,3828689909.15485,218.365264892578,1000.05786132813,,,6,,,,32.2846360056208,,,100,,,,,,,,,,,,,,,,,,,,,,218.135589599609,218.583938598633,1000.05786132813,1000.05786132813,,,7.66768026351929,-99999999,1,0,0,0,0.014801025390625,29.3255138397217,2,1,1,218.594940185547,0,2080379936,218.359246826172,,,0.00286544635670518,0.00014351179885836,0.00286899613629077,0.000143517790047983,0.942250907421112,0.969219148159027,32.1011734008789,0.189639121294022,30,4,200,-9.2587637482211E-5,-0.123003497719765,0.0209441352635622,1,,,,,,,,,,,,,,,,
,3828689989.07591,222.351043701172,1000.05786132813,,,6,,,,32.3069541730642,,,100,,,,,,,,,,,,,,,,,,,,,,222.121353149414,222.567398071289,1000.05786132813,1000.05786132813,,,7.67536544799805,-99999999,1,0,0,0,0.0147247314453125,30.3030319213867,2,1,1,222.58073425293,0,2080379872,222.342407226562,,,0.00282095444539639,0.000141282481033288,0.00282445129563271,0.000141288535786727,0.942374706268311,0.969441652297974,32.1235084533691,0.189630717039108,30,4,200,-8.9091932750307E-5,-0.112688116729259,0.0185956582427025,1,,,,,,,,,,,,,,,,
,3828690069.70823,226.365943908691,1000.05786132813,,,6,,,,32.3247526934425,,,100,,,,,,,,,,,,,,,,,,,,,,226.12663269043,226.593627929687,1000.05786132813,1000.05786132813,,,7.70716714859009,-99999999,1,0,0,0,0.013885498046875,29.8142719268799,2,1,1,226.605255126953,0,2080379936,226.363650512695,,,0.00277685448181189,0.000139062335836097,0.00278007903383503,0.000139067782318032,0.943819224834442,0.969700157642365,32.1471099853516,0.189609244465828,30,4,200,-9.1512942162808E-5,-0.113172143697739,0.0160252712666988,1,,,,,,,,,,,,,,,,
,3828690149.6688,230.353370666504,1000.05786132813,,,6,,,,32.3448442868013,,,100,,,,,,,,,,,,,,,,,,,,,,230.120254516602,230.576599121094,1000.05786132813,1000.05786132813,,,7.72116899490356,-99999999,1,0,0,0,0.013885498046875,29.8142719268799,2,1,1,230.586486816406,0,2080379776,230.351779174805,,,0.00273506481164841,0.000136964502016611,0.00273814211786125,0.000136969523411611,0.944482266902924,0.969819068908691,32.1698684692383,0.189606413245201,30,4,200,-8.92845273483545E-5,-0.113763332366943,0.0135185150429606,1,,,,,,,,,,,,,,,,
,3828690229.68835,234.359954833984,1000.05786132813,,,6,,,,32.3598875780435,,,100,,,,,,,,,,,,,,,,,,,,,,234.125274658203,234.57568359375,1000.05786132813,1000.05786132813,,,7.74702167510986,-99999999,1,0,0,0,0.013885498046875,29.8142719268799,2,1,1,234.594635009766,0,2080379776,234.346015930176,,,0.00269430519815639,0.000134906355606388,0.00269703490037143,0.000134911258272145,0.946793377399445,0.970301449298859,32.1940727233887,0.18960639834404,30,4,200,-0.000100043063866906,-0.114287346601486,0.0110387811437249,1,,,,,,,,,,,,,,,,
,3828690310.33275,238.377342224121,1000.05786132813,,,6,,,,32.3830424985598,,,100,,,,,,,,,,,,,,,,,,,,,,238.13916015625,238.603271484375,1000.05786132813,1000.05786132813,,,7.78941774368286,-99999999,1,0,0,0,0.0139617919921875,29.8142719268799,2,1,1,238.615524291992,0,2080379872,238.378147888184,,,0.00265386820169842,0.000132879278246861,0.00265652187917181,0.000132884003166485,0.94712495803833,0.970477700233459,32.2182960510254,0.189584165811539,30,4,200,-8.63816821947694E-5,-0.103968389332294,0.0194949824362993,1,,,,,,,,,,,,,,,,
,3828690390.13985,242.355880737305,1000.05786132813,,,6,,,,32.4031393106528,,,100,,,,,,,,,,,,,,,,,,,,,,242.128189086914,242.583572387695,1000.05786132813,1000.05786132813,,,7.83047246932983,-99999999,1,0,0,0,0.013885498046875,30.3030319213867,2,1,1,242.583572387695,0,2080379776,242.354019165039,,,0.00261564440500357,0.000130958241128879,0.00261813054302782,0.000130962904275364,0.948171555995941,0.970664441585541,32.2426643371582,0.189568638801575,30,4,200,-8.52014491101727E-5,-0.10456095635891,0.0170945413410664,1,,,,,,,,,,,,,,,,
,3828690470.38086,246.364295959473,1000.05786132813,,,6,,,,32.4233280481116,,,100,,,,,,,,,,,,,,,,,,,,,,246.127700805664,246.585311889648,1000.05786132813,1000.05786132813,,,7.87875127792358,-99999999,1,0,0,0,0.013885498046875,29.8142719268799,2,1,1,246.600891113281,0,2080380000,246.354066467285,,,0.0025781757675354,0.000129074272012864,0.0025804712663244,0.000129078169841254,0.949380218982697,0.97091794013977,32.2676849365234,0.189586028456688,30,4,200,-8.22379806777462E-5,-0.105194002389908,0.0147205786779523,1,,,,,,,,,,,,,,,,
,3828690550.63586,250.364219665527,1000.05786132813,,,6,,,,32.4438578884397,,,100,,,,,,,,,,,,,,,,,,,,,,250.123352050781,250.585556030273,1000.05786132813,1000.05786132813,,,7.92839193344116,-99999999,1,0,0,0,0.013885498046875,30.3030319213867,2,1,1,250.605087280273,0,2080379936,250.364492797852,,,0.0025418701134677,0.000127248828797469,0.00254399713819133,0.000127252850100042,0.950606524944305,0.971144139766693,32.293270111084,0.189556032419205,30,4,200,-8.30904173199087E-5,-0.105775371193886,0.0124013256281614,1,,,,,,,,,,,,,,,,
,3828690630.44688,254.354919433594,1000.05786132813,,,6,,,,32.4648870612715,,,100,,,,,,,,,,,,,,,,,,,,,,254.126617431641,254.563903808594,1000.05786132813,1000.05786132813,,,7.99014759063721,-99999999,1,0,0,0,0.013885498046875,29.8142719268799,2,1,1,254.602233886719,0,2080380000,254.346139526367,,,0.00250650720947923,0.000125470944886479,0.00250846456375309,0.000125474602168166,0.951840162277222,0.971385061740875,32.3193740844727,0.189537972211838,30,4,200,-7.96090462245047E-5,-0.106386736035347,0.0101279495283961,1,,,,,,,,,,,,,,,,